Workbook

Sheet BANK
A1: Day | B1: Date | C1: SALDO | D1: GLOBAL | E1: SISA USDT | F1: tambah modal | G1: OUT | H1: TOTAL | I1: PROFIT | K1: REMARK | L1: BCA | M1: BCA BISNIS | N1: BLU BCA | O1: MANDIRI | P1: BRI | Q1: BRI VEGA | R1: BNI | S1: SINARMAS | T1: TOTAL | U1: USDT | V1: RATE | W1: TOTAL USDT
A2: =IF(ISBLANK(B2),"",TEXT(B2,"dddd")) -> Wednesday | B2: 46267 | C2: START | D2: =T2 -> 0 | E2: 0 | H2: =SUM(D2+E2+F2) -> 0 | K2: START | L2: 0 | M2: 0 | N2: 0 | O2: 0 | P2: 0 | Q2: 0 | R2: 0 | S2: 0 | T2: =SUM(L2:S2) -> 0
C3: END | D3: =T3 -> 1894000 | E3: =W3 -> 9960071.5 | G3: 0 | H3: =SUM(D3+E3+F3+G3) -> 11854072 | I3: =H3-H2 -> 11854072 | K3: END | L3: 1894000 | M3: 0 | N3: 0 | O3: 0 | P3: 0 | Q3: 0 | R3: 0 | S3: 0 | T3: =SUM(J3:S3) -> 1894000 | U3: 564.31 | V3: 17650 | W3: =U3*V3 -> 9960071.5
A4: =IF(ISBLANK(B4),"",TEXT(B4,"dddd")) -> Thursday | B4: 46268 | C4: START | D4: =T4 -> 1894000 | K4: START | L4: 1894000 | M4: 0 | N4: 0 | O4: 0 | P4: 0 | Q4: 0 | R4: 0 | S4: 0 | T4: =SUM(L4:S4) -> 1894000 | W4: =U4*V4 -> 0
C5: END | D5: =T5 -> 31218000 | E5: =W5 -> -11190608 | G5: 1850000 | H5: =SUM(D5+E5+F5+G5) -> 21877392 | I5: =H5-H4 -> 21877392 | K5: END | L5: 6818000 | M5: 0 | N5: 24400000 | O5: 0 | P5: 0 | Q5: 0 | R5: 0 | S5: 0 | T5: =SUM(J5:S5) -> 31218000 | U5: -635.83 | V5: 17600 | W5: =U5*V5 -> -11190608
A6: =IF(ISBLANK(B6),"",TEXT(B6,"dddd")) -> Friday | B6: 46269 | C6: START | D6: =T6 -> 24418000 | K6: START | L6: 18000 | M6: 0 | N6: 24400000 | O6: 0 | P6: 0 | Q6: 0 | R6: 0 | S6: 0 | T6: =SUM(L6:S6) -> 24418000 | W6: =U6*V6 -> 0
C7: END | D7: =T7 -> 1309000 | E7: =W7 -> 15466000 | G7: 6800000 | H7: =SUM(D7+E7+F7+G7) -> 23575000 | I7: =H7-H6 -> 23575000 | K7: END | L7: 911000 | M7: 0 | N7: 398000 | O7: 0 | P7: 0 | Q7: 0 | R7: 0 | S7: 0 | T7: =SUM(J7:S7) -> 1309000 | U7: 880 | V7: 17575 | W7: =U7*V7 -> 15466000
A8: =IF(ISBLANK(B8),"",TEXT(B8,"dddd")) -> Saturday | B8: 46270 | C8: START | D8: =T8 -> 1309000 | K8: START | L8: 911000 | M8: 0 | N8: 398000 | O8: 0 | P8: 0 | Q8: 0 | R8: 0 | S8: 0 | T8: =SUM(L8:S8) -> 1309000 | W8: =U8*V8 -> 0
C9: END | D9: =T9 -> 0 | E9: =W9 -> 0 | G9: 5000000 | H9: =SUM(D9+E9+F9+G9) -> 5000000 | I9: =H9-H8 -> 5000000 | K9: END | R9: 0 | S9: 0 | T9: =SUM(J9:S9) -> 0 | W9: =U9*V9 -> 0
A10: =IF(ISBLANK(B10),"",TEXT(B10,"dddd")) -> Sunday | B10: 46271 | C10: START | D10: =T10 -> 0 | K10: START | R10: 0 | S10: 0 | T10: =SUM(L10:S10) -> 0 | W10: =U10*V10 -> 0
C11: END | D11: =T11 -> 0 | E11: =W11 -> 0 | I11: =H11-H10 -> 0 | K11: END | R11: 0 | S11: 0 | T11: =SUM(J11:S11) -> 0 | W11: =U11*V11 -> 0
A12: =IF(ISBLANK(B12),"",TEXT(B12,"dddd")) -> Saturday | B12: 46284 | C12: START | D12: =T12 -> 0 | K12: START | R12: 0 | S12: 0 | T12: =SUM(L12:S12) -> 0 | W12: =U12*V12 -> 0
C13: END | D13: =T13 -> 0 | E13: =W13 -> 0 | I13: =H13-H12 -> 0 | K13: END | R13: 0 | S13: 0 | T13: =SUM(J13:S13) -> 0 | W13: =U13*V13 -> 0
A14: =IF(ISBLANK(B14),"",TEXT(B14,"dddd")) -> Tuesday | B14: 46273 | C14: START | D14: =T14 -> 0 | K14: START | R14: 0 | S14: 0 | T14: =SUM(L14:S14) -> 0 | W14: =U14*V14 -> 0
C15: END | D15: =T15 -> 0 | E15: =W15 -> 0 | I15: =H15-H14 -> 0 | K15: END | R15: 0 | S15: 0 | T15: =SUM(J15:S15) -> 0 | W15: =U15*V15 -> 0
A16: =IF(ISBLANK(B16),"",TEXT(B16,"dddd")) -> Friday | B16: 46269 | C16: START | D16: =T16 -> 24418000 | K16: START | L16: 18000 | M16: 0 | N16: 24400000 | O16: 0 | P16: 0 | Q16: 0 | R16: 0 | S16: 0 | T16: =SUM(L16:S16) -> 24418000 | W16: =U16*V16 -> 0
C17: END | D17: =T17 -> 0 | E17: =W17 -> 0 | I17: =H17-H16 -> 0 | K17: END | R17: 0 | S17: 0 | T17: =SUM(J17:S17) -> 0 | W17: =U17*V17 -> 0
A18: =IF(ISBLANK(B18),"",TEXT(B18,"dddd")) -> Saturday | B18: 46270 | C18: START | D18: =T18 -> 0 | K18: START | R18: 0 | S18: 0 | T18: =SUM(L18:S18) -> 0 | W18: =U18*V18 -> 0
C19: END | D19: =T19 -> 0 | E19: =W19 -> 0 | I19: =H19-H18 -> 0 | K19: END | R19: 0 | S19: 0 | T19: =SUM(J19:S19) -> 0 | W19: =U19*V19 -> 0
A20: =IF(ISBLANK(B20),"",TEXT(B20,"dddd")) -> Sunday | B20: 46271 | C20: START | D20: =T20 -> 0 | K20: START | R20: 0 | S20: 0 | T20: =SUM(L20:S20) -> 0 | W20: =U20*V20 -> 0
C21: END | D21: =T21 -> 0 | E21: =W21 -> 0 | I21: =H21-H20 -> 0 | K21: END | R21: 0 | S21: 0 | T21: =SUM(J21:S21) -> 0 | W21: =U21*V21 -> 0
A22: =IF(ISBLANK(B22),"",TEXT(B22,"dddd")) -> Monday | B22: 46272 | C22: START | D22: =T22 -> 0 | K22: START | R22: 0 | S22: 0 | T22: =SUM(L22:S22) -> 0 | W22: =U22*V22 -> 0
C23: END | D23: =T23 -> 0 | E23: =W23 -> 0 | I23: =H23-H22 -> 0 | K23: END | R23: 0 | S23: 0 | T23: =SUM(J23:S23) -> 0 | W23: =U23*V23 -> 0
A24: =IF(ISBLANK(B24),"",TEXT(B24,"dddd")) -> Tuesday | B24: 46273 | C24: START | D24: =T24 -> 0 | K24: START | R24: 0 | S24: 0 | T24: =SUM(L24:S24) -> 0 | W24: =U24*V24 -> 0
C25: END | D25: =T25 -> 0 | E25: =W25 -> 0 | I25: =H25-H24 -> 0 | K25: END | R25: 0 | S25: 0 | T25: =SUM(J25:S25) -> 0 | W25: =U25*V25 -> 0
A26: =IF(ISBLANK(B26),"",TEXT(B26,"dddd")) -> Friday | B26: 46269 | C26: START | D26: =T26 -> 24418000 | K26: START | L26: 18000 | M26: 0 | N26: 24400000 | O26: 0 | P26: 0 | Q26: 0 | R26: 0 | S26: 0 | T26: =SUM(L26:S26) -> 24418000 | W26: =U26*V26 -> 0
C27: END | D27: =T27 -> 0 | E27: =W27 -> 0 | I27: =H27-H26 -> 0 | K27: END | R27: 0 | S27: 0 | T27: =SUM(J27:S27) -> 0 | W27: =U27*V27 -> 0
A28: =IF(ISBLANK(B28),"",TEXT(B28,"dddd")) -> Saturday | B28: 46270 | C28: START | D28: =T28 -> 0 | K28: START | R28: 0 | S28: 0 | T28: =SUM(L28:S28) -> 0 | W28: =U28*V28 -> 0
C29: END | D29: =T29 -> 0 | E29: =W29 -> 0 | I29: =H29-H28 -> 0 | K29: END | R29: 0 | S29: 0 | T29: =SUM(J29:S29) -> 0 | W29: =U29*V29 -> 0
A30: =IF(ISBLANK(B30),"",TEXT(B30,"dddd")) -> Sunday | B30: 46271 | C30: START | D30: =T30 -> 0 | K30: START | R30: 0 | S30: 0 | T30: =SUM(L30:S30) -> 0 | W30: =U30*V30 -> 0
C31: END | D31: =T31 -> 0 | E31: =W31 -> 0 | I31: =H31-H30 -> 0 | K31: END | R31: 0 | S31: 0 | T31: =SUM(J31:S31) -> 0 | W31: =U31*V31 -> 0
A32: =IF(ISBLANK(B32),"",TEXT(B32,"dddd")) -> Monday | B32: 46272 | C32: START | D32: =T32 -> 0 | K32: START | R32: 0 | S32: 0 | T32: =SUM(L32:S32) -> 0 | W32: =U32*V32 -> 0
C33: END | D33: =T33 -> 0 | E33: =W33 -> 0 | I33: =H33-H32 -> 0 | K33: END | R33: 0 | S33: 0 | T33: =SUM(J33:S33) -> 0 | W33: =U33*V33 -> 0
A34: =IF(ISBLANK(B34),"",TEXT(B34,"dddd")) -> Tuesday | B34: 46273 | C34: START | D34: =T34 -> 0 | K34: START | R34: 0 | S34: 0 | T34: =SUM(L34:S34) -> 0 | W34: =U34*V34 -> 0
C35: END | D35: =T35 -> 0 | E35: =W35 -> 0 | I35: =H35-H34 -> 0 | K35: END | R35: 0 | S35: 0 | T35: =SUM(J35:S35) -> 0 | W35: =U35*V35 -> 0
A36: =IF(ISBLANK(B36),"",TEXT(B36,"dddd")) -> Friday | B36: 46269 | C36: START | D36: =T36 -> 24418000 | K36: START | L36: 18000 | M36: 0 | N36: 24400000 | O36: 0 | P36: 0 | Q36: 0 | R36: 0 | S36: 0 | T36: =SUM(L36:S36) -> 24418000 | W36: =U36*V36 -> 0
C37: END | D37: =T37 -> 0 | E37: =W37 -> 0 | I37: =H37-H36 -> 0 | K37: END | R37: 0 | S37: 0 | T37: =SUM(J37:S37) -> 0 | W37: =U37*V37 -> 0
A38: =IF(ISBLANK(B38),"",TEXT(B38,"dddd")) -> Saturday | B38: 46270 | C38: START | D38: =T38 -> 0 | K38: START | R38: 0 | S38: 0 | T38: =SUM(L38:S38) -> 0 | W38: =U38*V38 -> 0
C39: END | D39: =T39 -> 0 | E39: =W39 -> 0 | I39: =H39-H38 -> 0 | K39: END | R39: 0 | S39: 0 | T39: =SUM(J39:S39) -> 0 | W39: =U39*V39 -> 0
A40: =IF(ISBLANK(B40),"",TEXT(B40,"dddd")) -> Sunday | B40: 46271 | C40: START | D40: =T40 -> 0 | K40: START | R40: 0 | S40: 0 | T40: =SUM(L40:S40) -> 0 | W40: =U40*V40 -> 0
...

Sheet SUMMARY
A1: p | C1: EXCHANGE | N1: MONTHLY
A2: DAY | B2: DATE | C2: NOMINAL | D2: RATE BUY | E2: BUY | F2: RATE SELL | G2: SELL | H2: FEE | I2: OMSET | J2: PROFIT | N2: MONTH | O2: NOMINAL | P2: RATE BUY | Q2: BUY | R2: RATE SELL | S2: SELL | T2: FEE | U2: PROFIT
T3: 0.0007
A4: AUG | N4: =IFERROR(__xludf.DUMMYFUNCTION("UNIQUE(FILTER(A2:A153,(A2:A153<>"""")*(COUNTIF(LEGEND!B2:B13,A2:A153)>0)))"),"AUG") -> AUG | O4: =IFERROR(SUM( INDEX($C:$C,MATCH($N4,$A:$A,0)+1): INDEX($C:$C,MATCH($N4&"_TOTAL",$A:$A,0)-1) ),0) -> 1139465.6 | P4: =IFERROR(AVERAGE( INDEX(D:D,MATCH($N4,$A:$A,0)+1): INDEX(D:D,MATCH($N4&"_TOTAL",$A:$A,0)-1) ),0) -> 17737.582 | Q4: =IFERROR(SUM( INDEX(E:E,MATCH($N4,$A:$A,0)+1): INDEX(E:E,MATCH($N4&"_TOTAL",$A:$A,0)-1) ),0) -> 20209889639 | R4: =IFERROR(AVERAGE( INDEX(F:F,MATCH($N4,$A:$A,0)+1): INDEX(F:F,MATCH($N4&"_TOTAL",$A:$A,0)-1) ),0) -> 17762.5 | S4: =IFERROR(SUM( INDEX(G:G,MATCH($N4,$A:$A,0)+1): INDEX(G:G,MATCH($N4&"_TOTAL",$A:$A,0)-1) ),0) -> 20249998209 | T4: =IFERROR(SUM( INDEX(H:H,MATCH($N4,$A:$A,0)+1): INDEX(H:H,MATCH($N4&"_TOTAL",$A:$A,0)-1) ),0) -> 14146923 | U4: =IFERROR(SUM( INDEX(J:J,MATCH($N4,$A:$A,0)+1): INDEX(J:J,MATCH($N4&"_TOTAL",$A:$A,0)-1) ),0) -> 25961647
A5: =IF(ISBLANK(B5),"",TEXT(B5,"dddd")) -> Saturday | B5: 46235 | C5: =SUMIF(AUG!$B$3:$B$100, B5, AUG!$D$3:$D$100) -> 0 | D5: =IFERROR(__xludf.DUMMYFUNCTION("IFNA(INDEX(FILTER(AUG!$E$3:$E$100, AUG!$B$3:$B$100=B5), 1), ""-"")"),"-") -> - | E5: =SUMIF(AUG!$B$3:$B$100, B5, AUG!$F$3:$F$100) -> 0 | F5: =IFERROR(__xludf.DUMMYFUNCTION("IFNA(INDEX(FILTER(AUG!$G$3:$G$100, AUG!$B$3:$B$100=B5), 1), ""-"")"),"-") -> - | G5: =IFNA(SUMIF(AUG!$B$3:$B$100,B5,AUG!$H$3:$H$100),"-") -> 0 | H5: =E5*0.07% -> 0 | I5: =SUMIF(AUG!B:B, B5, AUG!K:K) -> 0 | J5: =G5-E5-H5 -> 0 | N5: =IFERROR(__xludf.DUMMYFUNCTION("""COMPUTED_VALUE"""),"SEP") -> SEP | O5: =IFERROR(SUM( INDEX($C:$C,MATCH($N5,$A:$A,0)+1): INDEX($C:$C,MATCH($N5&"_TOTAL",$A:$A,0)-1) ),0) -> 11639891 | P5: =IFERROR(AVERAGE( INDEX(D:D,MATCH($N5,$A:$A,0)+1): INDEX(D:D,MATCH($N5&"_TOTAL",$A:$A,0)-1) ),0) -> 17635.512 | Q5: =IFERROR(SUM( INDEX(E:E,MATCH($N5,$A:$A,0)+1): INDEX(E:E,MATCH($N5&"_TOTAL",$A:$A,0)-1) ),0) -> 205573414297 | R5: =IFERROR(AVERAGE( INDEX(F:F,MATCH($N5,$A:$A,0)+1): INDEX(F:F,MATCH($N5&"_TOTAL",$A:$A,0)-1) ),0) -> 17663.643 | S5: =IFERROR(SUM( INDEX(G:G,MATCH($N5,$A:$A,0)+1): INDEX(G:G,MATCH($N5&"_TOTAL",$A:$A,0)-1) ),0) -> 205910516613 | T5: =IFERROR(SUM( INDEX(H:H,MATCH($N5,$A:$A,0)+1): INDEX(H:H,MATCH($N5&"_TOTAL",$A:$A,0)-1) ),0) -> 43454634 | U5: =IFERROR(SUM( INDEX(J:J,MATCH($N5,$A:$A,0)+1): INDEX(J:J,MATCH($N5&"_TOTAL",$A:$A,0)-1) ),0) -> 2.9364768e+08
A6: =IF(ISBLANK(B6),"",TEXT(B6,"dddd")) -> Sunday | B6: 46236 | C6: =SUMIF(AUG!$B$3:$B$100, B6, AUG!$D$3:$D$100) -> 0 | D6: =IFERROR(__xludf.DUMMYFUNCTION("IFNA(INDEX(FILTER(AUG!$E$3:$E$100, AUG!$B$3:$B$100=B6), 1), ""-"")"),"-") -> - | E6: =SUMIF(AUG!$B$3:$B$100, B6, AUG!$F$3:$F$100) -> 0 | F6: =IFERROR(__xludf.DUMMYFUNCTION("IFNA(INDEX(FILTER(AUG!$G$3:$G$100, AUG!$B$3:$B$100=B6), 1), ""-"")"),"-") -> - | G6: =IFNA(SUMIF(AUG!$B$3:$B$100,B6,AUG!$H$3:$H$100),"-") -> 0 | H6: =E6*0.07% -> 0 | I6: =SUMIF(AUG!B:B, B6, AUG!K:K) -> 0 | J6: =G6-E6-H6 -> 0 | N6: =IFERROR(__xludf.DUMMYFUNCTION("""COMPUTED_VALUE"""),"OCT") -> OCT | O6: =IFERROR(SUM( INDEX($C:$C,MATCH($N6,$A:$A,0)+1): INDEX($C:$C,MATCH($N6&"_TOTAL",$A:$A,0)-1) ),0) -> 0 | P6: =IFERROR(AVERAGE( INDEX(D:D,MATCH($N6,$A:$A,0)+1): INDEX(D:D,MATCH($N6&"_TOTAL",$A:$A,0)-1) ),0) -> 0 | Q6: =IFERROR(SUM( INDEX(E:E,MATCH($N6,$A:$A,0)+1): INDEX(E:E,MATCH($N6&"_TOTAL",$A:$A,0)-1) ),0) -> 0 | R6: =IFERROR(AVERAGE( INDEX(F:F,MATCH($N6,$A:$A,0)+1): INDEX(F:F,MATCH($N6&"_TOTAL",$A:$A,0)-1) ),0) -> 0 | S6: =IFERROR(SUM( INDEX(G:G,MATCH($N6,$A:$A,0)+1): INDEX(G:G,MATCH($N6&"_TOTAL",$A:$A,0)-1) ),0) -> 0 | T6: =IFERROR(SUM( INDEX(H:H,MATCH($N6,$A:$A,0)+1): INDEX(H:H,MATCH($N6&"_TOTAL",$A:$A,0)-1) ),0) -> 0 | U6: =IFERROR(SUM( INDEX(J:J,MATCH($N6,$A:$A,0)+1): INDEX(J:J,MATCH($N6&"_TOTAL",$A:$A,0)-1) ),0) -> 0
A7: =IF(ISBLANK(B7),"",TEXT(B7,"dddd")) -> Monday | B7: 46237 | C7: =SUMIF(AUG!$B$3:$B$100, B7, AUG!$D$3:$D$100) -> 0 | D7: =IFERROR(__xludf.DUMMYFUNCTION("IFNA(INDEX(FILTER(AUG!$E$3:$E$100, AUG!$B$3:$B$100=B7), 1), ""-"")"),"-") -> - | E7: =SUMIF(AUG!$B$3:$B$100, B7, AUG!$F$3:$F$100) -> 0 | F7: =IFERROR(__xludf.DUMMYFUNCTION("IFNA(INDEX(FILTER(AUG!$G$3:$G$100, AUG!$B$3:$B$100=B7), 1), ""-"")"),"-") -> - | G7: =IFNA(SUMIF(AUG!$B$3:$B$100,B7,AUG!$H$3:$H$100),"-") -> 0 | H7: =E7*0.07% -> 0 | I7: =SUMIF(AUG!B:B, B7, AUG!K:K) -> 0 | J7: =G7-E7-H7 -> 0 | N7: =IFERROR(__xludf.DUMMYFUNCTION("""COMPUTED_VALUE"""),"NOV") -> NOV | O7: =IFERROR(SUM( INDEX($C:$C,MATCH($N7,$A:$A,0)+1): INDEX($C:$C,MATCH($N7&"_TOTAL",$A:$A,0)-1) ),0) -> 0 | P7: =IFERROR(AVERAGE( INDEX(D:D,MATCH($N7,$A:$A,0)+1): INDEX(D:D,MATCH($N7&"_TOTAL",$A:$A,0)-1) ),0) -> 0 | Q7: =IFERROR(SUM( INDEX(E:E,MATCH($N7,$A:$A,0)+1): INDEX(E:E,MATCH($N7&"_TOTAL",$A:$A,0)-1) ),0) -> 0 | R7: =IFERROR(AVERAGE( INDEX(F:F,MATCH($N7,$A:$A,0)+1): INDEX(F:F,MATCH($N7&"_TOTAL",$A:$A,0)-1) ),0) -> 0 | S7: =IFERROR(SUM( INDEX(G:G,MATCH($N7,$A:$A,0)+1): INDEX(G:G,MATCH($N7&"_TOTAL",$A:$A,0)-1) ),0) -> 0 | T7: =IFERROR(SUM( INDEX(H:H,MATCH($N7,$A:$A,0)+1): INDEX(H:H,MATCH($N7&"_TOTAL",$A:$A,0)-1) ),0) -> 0 | U7: =IFERROR(SUM( INDEX(J:J,MATCH($N7,$A:$A,0)+1): INDEX(J:J,MATCH($N7&"_TOTAL",$A:$A,0)-1) ),0) -> 0
A8: =IF(ISBLANK(B8),"",TEXT(B8,"dddd")) -> Tuesday | B8: 46238 | C8: =SUMIF(AUG!$B$3:$B$100, B8, AUG!$D$3:$D$100) -> 0 | D8: =IFERROR(__xludf.DUMMYFUNCTION("IFNA(INDEX(FILTER(AUG!$E$3:$E$100, AUG!$B$3:$B$100=B8), 1), ""-"")"),"-") -> - | E8: =SUMIF(AUG!$B$3:$B$100, B8, AUG!$F$3:$F$100) -> 0 | F8: =IFERROR(__xludf.DUMMYFUNCTION("IFNA(INDEX(FILTER(AUG!$G$3:$G$100, AUG!$B$3:$B$100=B8), 1), ""-"")"),"-") -> - | G8: =IFNA(SUMIF(AUG!$B$3:$B$100,B8,AUG!$H$3:$H$100),"-") -> 0 | H8: =E8*0.07% -> 0 | I8: =SUMIF(AUG!B:B, B8, AUG!K:K) -> 0 | J8: =G8-E8-H8 -> 0 | N8: =IFERROR(__xludf.DUMMYFUNCTION("""COMPUTED_VALUE"""),"DEC") -> DEC | O8: =IFERROR(SUM( INDEX($C:$C,MATCH($N8,$A:$A,0)+1): INDEX($C:$C,MATCH($N8&"_TOTAL",$A:$A,0)-1) ),0) -> 0 | P8: =IFERROR(AVERAGE( INDEX(D:D,MATCH($N8,$A:$A,0)+1): INDEX(D:D,MATCH($N8&"_TOTAL",$A:$A,0)-1) ),0) -> 0 | Q8: =IFERROR(SUM( INDEX(E:E,MATCH($N8,$A:$A,0)+1): INDEX(E:E,MATCH($N8&"_TOTAL",$A:$A,0)-1) ),0) -> 0 | R8: =IFERROR(AVERAGE( INDEX(F:F,MATCH($N8,$A:$A,0)+1): INDEX(F:F,MATCH($N8&"_TOTAL",$A:$A,0)-1) ),0) -> 0 | S8: =IFERROR(SUM( INDEX(G:G,MATCH($N8,$A:$A,0)+1): INDEX(G:G,MATCH($N8&"_TOTAL",$A:$A,0)-1) ),0) -> 0 | T8: =IFERROR(SUM( INDEX(H:H,MATCH($N8,$A:$A,0)+1): INDEX(H:H,MATCH($N8&"_TOTAL",$A:$A,0)-1) ),0) -> 0 | U8: =IFERROR(SUM( INDEX(J:J,MATCH($N8,$A:$A,0)+1): INDEX(J:J,MATCH($N8&"_TOTAL",$A:$A,0)-1) ),0) -> 0
A9: =IF(ISBLANK(B9),"",TEXT(B9,"dddd")) -> Wednesday | B9: 46239 | C9: =SUMIF(AUG!$B$3:$B$100, B9, AUG!$D$3:$D$100) -> 0 | D9: =IFERROR(__xludf.DUMMYFUNCTION("IFNA(INDEX(FILTER(AUG!$E$3:$E$100, AUG!$B$3:$B$100=B9), 1), ""-"")"),"-") -> - | E9: =SUMIF(AUG!$B$3:$B$100, B9, AUG!$F$3:$F$100) -> 0 | F9: =IFERROR(__xludf.DUMMYFUNCTION("IFNA(INDEX(FILTER(AUG!$G$3:$G$100, AUG!$B$3:$B$100=B9), 1), ""-"")"),"-") -> - | G9: =IFNA(SUMIF(AUG!$B$3:$B$100,B9,AUG!$H$3:$H$100),"-") -> 0 | H9: =E9*0.07% -> 0 | I9: =SUMIF(AUG!B:B, B9, AUG!K:K) -> 0 | J9: =G9-E9-H9 -> 0 | O9: =IFERROR(SUM( INDEX($C:$C,MATCH($N9,$A:$A,0)+1): INDEX($C:$C,MATCH($N9&"_TOTAL",$A:$A,0)-1) ),0) -> 0 | P9: =IFERROR(AVERAGE( INDEX(D:D,MATCH($N9,$A:$A,0)+1): INDEX(D:D,MATCH($N9&"_TOTAL",$A:$A,0)-1) ),0) -> 0 | Q9: =IFERROR(SUM( INDEX(E:E,MATCH($N9,$A:$A,0)+1): INDEX(E:E,MATCH($N9&"_TOTAL",$A:$A,0)-1) ),0) -> 0 | R9: =IFERROR(AVERAGE( INDEX(F:F,MATCH($N9,$A:$A,0)+1): INDEX(F:F,MATCH($N9&"_TOTAL",$A:$A,0)-1) ),0) -> 0 | S9: =IFERROR(SUM( INDEX(G:G,MATCH($N9,$A:$A,0)+1): INDEX(G:G,MATCH($N9&"_TOTAL",$A:$A,0)-1) ),0) -> 0 | T9: =IFERROR(SUM( INDEX(H:H,MATCH($N9,$A:$A,0)+1): INDEX(H:H,MATCH($N9&"_TOTAL",$A:$A,0)-1) ),0) -> 0 | U9: =IFERROR(SUM( INDEX(J:J,MATCH($N9,$A:$A,0)+1): INDEX(J:J,MATCH($N9&"_TOTAL",$A:$A,0)-1) ),0) -> 0
A10: =IF(ISBLANK(B10),"",TEXT(B10,"dddd")) -> Thursday | B10: 46240 | C10: =SUMIF(AUG!$B$3:$B$100, B10, AUG!$D$3:$D$100) -> 0 | D10: =IFERROR(__xludf.DUMMYFUNCTION("IFNA(INDEX(FILTER(AUG!$E$3:$E$100, AUG!$B$3:$B$100=B10), 1), ""-"")"),"-") -> - | E10: =SUMIF(AUG!$B$3:$B$100, B10, AUG!$F$3:$F$100) -> 0 | F10: =IFERROR(__xludf.DUMMYFUNCTION("IFNA(INDEX(FILTER(AUG!$G$3:$G$100, AUG!$B$3:$B$100=B10), 1), ""-"")"),"-") -> - | G10: =IFNA(SUMIF(AUG!$B$3:$B$100,B10,AUG!$H$3:$H$100),"-") -> 0 | H10: =E10*0.07% -> 0 | I10: =SUMIF(AUG!B:B, B10, AUG!K:K) -> 0 | J10: =G10-E10-H10 -> 0 | O10: =IFERROR(SUM( INDEX($C:$C,MATCH($N10,$A:$A,0)+1): INDEX($C:$C,MATCH($N10&"_TOTAL",$A:$A,0)-1) ),0) -> 0 | P10: =IFERROR(AVERAGE( INDEX(D:D,MATCH($N10,$A:$A,0)+1): INDEX(D:D,MATCH($N10&"_TOTAL",$A:$A,0)-1) ),0) -> 0 | Q10: =IFERROR(SUM( INDEX(E:E,MATCH($N10,$A:$A,0)+1): INDEX(E:E,MATCH($N10&"_TOTAL",$A:$A,0)-1) ),0) -> 0 | R10: =IFERROR(AVERAGE( INDEX(F:F,MATCH($N10,$A:$A,0)+1): INDEX(F:F,MATCH($N10&"_TOTAL",$A:$A,0)-1) ),0) -> 0 | S10: =IFERROR(SUM( INDEX(G:G,MATCH($N10,$A:$A,0)+1): INDEX(G:G,MATCH($N10&"_TOTAL",$A:$A,0)-1) ),0) -> 0 | T10: =IFERROR(SUM( INDEX(H:H,MATCH($N10,$A:$A,0)+1): INDEX(H:H,MATCH($N10&"_TOTAL",$A:$A,0)-1) ),0) -> 0 | U10: =IFERROR(SUM( INDEX(J:J,MATCH($N10,$A:$A,0)+1): INDEX(J:J,MATCH($N10&"_TOTAL",$A:$A,0)-1) ),0) -> 0
A11: =IF(ISBLANK(B11),"",TEXT(B11,"dddd")) -> Friday | B11: 46241 | C11: =SUMIF(AUG!$B$3:$B$100, B11, AUG!$D$3:$D$100) -> 0 | D11: =IFERROR(__xludf.DUMMYFUNCTION("IFNA(INDEX(FILTER(AUG!$E$3:$E$100, AUG!$B$3:$B$100=B11), 1), ""-"")"),"-") -> - | E11: =SUMIF(AUG!$B$3:$B$100, B11, AUG!$F$3:$F$100) -> 0 | F11: =IFERROR(__xludf.DUMMYFUNCTION("IFNA(INDEX(FILTER(AUG!$G$3:$G$100, AUG!$B$3:$B$100=B11), 1), ""-"")"),"-") -> - | G11: =IFNA(SUMIF(AUG!$B$3:$B$100,B11,AUG!$H$3:$H$100),"-") -> 0 | H11: =E11*0.07% -> 0 | I11: =SUMIF(AUG!B:B, B11, AUG!K:K) -> 0 | J11: =G11-E11-H11 -> 0 | O11: =IFERROR(SUM( INDEX($C:$C,MATCH($N11,$A:$A,0)+1): INDEX($C:$C,MATCH($N11&"_TOTAL",$A:$A,0)-1) ),0) -> 0 | P11: =IFERROR(AVERAGE( INDEX(D:D,MATCH($N11,$A:$A,0)+1): INDEX(D:D,MATCH($N11&"_TOTAL",$A:$A,0)-1) ),0) -> 0 | Q11: =IFERROR(SUM( INDEX(E:E,MATCH($N11,$A:$A,0)+1): INDEX(E:E,MATCH($N11&"_TOTAL",$A:$A,0)-1) ),0) -> 0 | R11: =IFERROR(AVERAGE( INDEX(F:F,MATCH($N11,$A:$A,0)+1): INDEX(F:F,MATCH($N11&"_TOTAL",$A:$A,0)-1) ),0) -> 0 | S11: =IFERROR(SUM( INDEX(G:G,MATCH($N11,$A:$A,0)+1): INDEX(G:G,MATCH($N11&"_TOTAL",$A:$A,0)-1) ),0) -> 0 | T11: =IFERROR(SUM( INDEX(H:H,MATCH($N11,$A:$A,0)+1): INDEX(H:H,MATCH($N11&"_TOTAL",$A:$A,0)-1) ),0) -> 0 | U11: =IFERROR(SUM( INDEX(J:J,MATCH($N11,$A:$A,0)+1): INDEX(J:J,MATCH($N11&"_TOTAL",$A:$A,0)-1) ),0) -> 0
A12: =IF(ISBLANK(B12),"",TEXT(B12,"dddd")) -> Saturday | B12: 46242 | C12: =SUMIF(AUG!$B$3:$B$100, B12, AUG!$D$3:$D$100) -> 0 | D12: =IFERROR(__xludf.DUMMYFUNCTION("IFNA(INDEX(FILTER(AUG!$E$3:$E$100, AUG!$B$3:$B$100=B12), 1), ""-"")"),"-") -> - | E12: =SUMIF(AUG!$B$3:$B$100, B12, AUG!$F$3:$F$100) -> 0 | F12: =IFERROR(__xludf.DUMMYFUNCTION("IFNA(INDEX(FILTER(AUG!$G$3:$G$100, AUG!$B$3:$B$100=B12), 1), ""-"")"),"-") -> - | G12: =IFNA(SUMIF(AUG!$B$3:$B$100,B12,AUG!$H$3:$H$100),"-") -> 0 | H12: =E12*0.07% -> 0 | I12: =SUMIF(AUG!B:B, B12, AUG!K:K) -> 0 | J12: =G12-E12-H12 -> 0 | O12: =IFERROR(SUM( INDEX($C:$C,MATCH($N12,$A:$A,0)+1): INDEX($C:$C,MATCH($N12&"_TOTAL",$A:$A,0)-1) ),0) -> 0 | P12: =IFERROR(AVERAGE( INDEX(D:D,MATCH($N12,$A:$A,0)+1): INDEX(D:D,MATCH($N12&"_TOTAL",$A:$A,0)-1) ),0) -> 0 | Q12: =IFERROR(SUM( INDEX(E:E,MATCH($N12,$A:$A,0)+1): INDEX(E:E,MATCH($N12&"_TOTAL",$A:$A,0)-1) ),0) -> 0 | R12: =IFERROR(AVERAGE( INDEX(F:F,MATCH($N12,$A:$A,0)+1): INDEX(F:F,MATCH($N12&"_TOTAL",$A:$A,0)-1) ),0) -> 0 | S12: =IFERROR(SUM( INDEX(G:G,MATCH($N12,$A:$A,0)+1): INDEX(G:G,MATCH($N12&"_TOTAL",$A:$A,0)-1) ),0) -> 0 | T12: =IFERROR(SUM( INDEX(H:H,MATCH($N12,$A:$A,0)+1): INDEX(H:H,MATCH($N12&"_TOTAL",$A:$A,0)-1) ),0) -> 0 | U12: =IFERROR(SUM( INDEX(J:J,MATCH($N12,$A:$A,0)+1): INDEX(J:J,MATCH($N12&"_TOTAL",$A:$A,0)-1) ),0) -> 0
A13: =IF(ISBLANK(B13),"",TEXT(B13,"dddd")) -> Sunday | B13: 46243 | C13: =SUMIF(AUG!$B$3:$B$100, B13, AUG!$D$3:$D$100) -> 0 | D13: =IFERROR(__xludf.DUMMYFUNCTION("IFNA(INDEX(FILTER(AUG!$E$3:$E$100, AUG!$B$3:$B$100=B13), 1), ""-"")"),"-") -> - | E13: =SUMIF(AUG!$B$3:$B$100, B13, AUG!$F$3:$F$100) -> 0 | F13: =IFERROR(__xludf.DUMMYFUNCTION("IFNA(INDEX(FILTER(AUG!$G$3:$G$100, AUG!$B$3:$B$100=B13), 1), ""-"")"),"-") -> - | G13: =IFNA(SUMIF(AUG!$B$3:$B$100,B13,AUG!$H$3:$H$100),"-") -> 0 | H13: =E13*0.07% -> 0 | I13: =SUMIF(AUG!B:B, B13, AUG!K:K) -> 0 | J13: =G13-E13-H13 -> 0 | O13: =IFERROR(SUM( INDEX($C:$C,MATCH($N13,$A:$A,0)+1): INDEX($C:$C,MATCH($N13&"_TOTAL",$A:$A,0)-1) ),0) -> 0 | P13: =IFERROR(AVERAGE( INDEX(D:D,MATCH($N13,$A:$A,0)+1): INDEX(D:D,MATCH($N13&"_TOTAL",$A:$A,0)-1) ),0) -> 0 | Q13: =IFERROR(SUM( INDEX(E:E,MATCH($N13,$A:$A,0)+1): INDEX(E:E,MATCH($N13&"_TOTAL",$A:$A,0)-1) ),0) -> 0 | R13: =IFERROR(AVERAGE( INDEX(F:F,MATCH($N13,$A:$A,0)+1): INDEX(F:F,MATCH($N13&"_TOTAL",$A:$A,0)-1) ),0) -> 0 | S13: =IFERROR(SUM( INDEX(G:G,MATCH($N13,$A:$A,0)+1): INDEX(G:G,MATCH($N13&"_TOTAL",$A:$A,0)-1) ),0) -> 0 | T13: =IFERROR(SUM( INDEX(H:H,MATCH($N13,$A:$A,0)+1): INDEX(H:H,MATCH($N13&"_TOTAL",$A:$A,0)-1) ),0) -> 0 | U13: =IFERROR(SUM( INDEX(J:J,MATCH($N13,$A:$A,0)+1): INDEX(J:J,MATCH($N13&"_TOTAL",$A:$A,0)-1) ),0) -> 0
A14: =IF(ISBLANK(B14),"",TEXT(B14,"dddd")) -> Monday | B14: 46244 | C14: =SUMIF(AUG!$B$3:$B$100, B14, AUG!$D$3:$D$100) -> 169571.35 | D14: =IFERROR(__xludf.DUMMYFUNCTION("IFNA(INDEX(FILTER(AUG!$E$3:$E$100, AUG!$B$3:$B$100=B14), 1), ""-"")"),17664.016100178887) -> 17664.016 | E14: =SUMIF(AUG!$B$3:$B$100, B14, AUG!$F$3:$F$100) -> 2995016202 | F14: =IFERROR(__xludf.DUMMYFUNCTION("IFNA(INDEX(FILTER(AUG!$G$3:$G$100, AUG!$B$3:$B$100=B14), 1), ""-"")"),17690.0) -> 17690 | G14: =IFNA(SUMIF(AUG!$B$3:$B$100,B14,AUG!$H$3:$H$100),"-") -> 2999999747 | H14: =E14*0.07% -> 2096511.3 | I14: =SUMIF(AUG!B:B, B14, AUG!K:K) -> 4983544.9 | J14: =G14-E14-H14 -> 2887033.6 | O14: =IFERROR(SUM( INDEX($C:$C,MATCH($N14,$A:$A,0)+1): INDEX($C:$C,MATCH($N14&"_TOTAL",$A:$A,0)-1) ),0) -> 0 | P14: =IFERROR(AVERAGE( INDEX(D:D,MATCH($N14,$A:$A,0)+1): INDEX(D:D,MATCH($N14&"_TOTAL",$A:$A,0)-1) ),0) -> 0 | Q14: =IFERROR(SUM( INDEX(E:E,MATCH($N14,$A:$A,0)+1): INDEX(E:E,MATCH($N14&"_TOTAL",$A:$A,0)-1) ),0) -> 0 | R14: =IFERROR(AVERAGE( INDEX(F:F,MATCH($N14,$A:$A,0)+1): INDEX(F:F,MATCH($N14&"_TOTAL",$A:$A,0)-1) ),0) -> 0 | S14: =IFERROR(SUM( INDEX(G:G,MATCH($N14,$A:$A,0)+1): INDEX(G:G,MATCH($N14&"_TOTAL",$A:$A,0)-1) ),0) -> 0 | T14: =IFERROR(SUM( INDEX(H:H,MATCH($N14,$A:$A,0)+1): INDEX(H:H,MATCH($N14&"_TOTAL",$A:$A,0)-1) ),0) -> 0 | U14: =IFERROR(SUM( INDEX(J:J,MATCH($N14,$A:$A,0)+1): INDEX(J:J,MATCH($N14&"_TOTAL",$A:$A,0)-1) ),0) -> 0
A15: =IF(ISBLANK(B15),"",TEXT(B15,"dddd")) -> Tuesday | B15: 46245 | C15: =SUMIF(AUG!$B$3:$B$100, B15, AUG!$D$3:$D$100) -> 112867.13 | D15: =IFERROR(__xludf.DUMMYFUNCTION("IFNA(INDEX(FILTER(AUG!$E$3:$E$100, AUG!$B$3:$B$100=B15), 1), ""-"")"),17706.222945928384) -> 17706.223 | E15: =SUMIF(AUG!$B$3:$B$100, B15, AUG!$F$3:$F$100) -> 1998872404 | F15: =IFERROR(__xludf.DUMMYFUNCTION("IFNA(INDEX(FILTER(AUG!$G$3:$G$100, AUG!$B$3:$B$100=B15), 1), ""-"")"),17690.0) -> 17690 | G15: =IFNA(SUMIF(AUG!$B$3:$B$100,B15,AUG!$H$3:$H$100),"-") -> 1999999811 | H15: =E15*0.07% -> 1399210.7 | I15: =SUMIF(AUG!B:B, B15, AUG!K:K) -> 1127407.3 | J15: =G15-E15-H15 -> -271803.38 | O15: =IFERROR(SUM( INDEX($C:$C,MATCH($N15,$A:$A,0)+1): INDEX($C:$C,MATCH($N15&"_TOTAL",$A:$A,0)-1) ),0) -> 0 | P15: =IFERROR(AVERAGE( INDEX(D:D,MATCH($N15,$A:$A,0)+1): INDEX(D:D,MATCH($N15&"_TOTAL",$A:$A,0)-1) ),0) -> 0 | Q15: =IFERROR(SUM( INDEX(E:E,MATCH($N15,$A:$A,0)+1): INDEX(E:E,MATCH($N15&"_TOTAL",$A:$A,0)-1) ),0) -> 0 | R15: =IFERROR(AVERAGE( INDEX(F:F,MATCH($N15,$A:$A,0)+1): INDEX(F:F,MATCH($N15&"_TOTAL",$A:$A,0)-1) ),0) -> 0 | S15: =IFERROR(SUM( INDEX(G:G,MATCH($N15,$A:$A,0)+1): INDEX(G:G,MATCH($N15&"_TOTAL",$A:$A,0)-1) ),0) -> 0 | T15: =IFERROR(SUM( INDEX(H:H,MATCH($N15,$A:$A,0)+1): INDEX(H:H,MATCH($N15&"_TOTAL",$A:$A,0)-1) ),0) -> 0 | U15: =IFERROR(SUM( INDEX(J:J,MATCH($N15,$A:$A,0)+1): INDEX(J:J,MATCH($N15&"_TOTAL",$A:$A,0)-1) ),0) -> 0
A16: =IF(ISBLANK(B16),"",TEXT(B16,"dddd")) -> Wednesday | B16: 46246 | C16: =SUMIF(AUG!$B$3:$B$100, B16, AUG!$D$3:$D$100) -> 280725.49 | D16: =IFERROR(__xludf.DUMMYFUNCTION("IFNA(INDEX(FILTER(AUG!$E$3:$E$100, AUG!$B$3:$B$100=B16), 1), ""-"")"),17778.171636799914) -> 17778.172 | E16: =SUMIF(AUG!$B$3:$B$100, B16, AUG!$F$3:$F$100) -> 4988596546 | F16: =IFERROR(__xludf.DUMMYFUNCTION("IFNA(INDEX(FILTER(AUG!$G$3:$G$100, AUG!$B$3:$B$100=B16), 1), ""-"")"),17825.0) -> 17825 | G16: =IFNA(SUMIF(AUG!$B$3:$B$100,B16,AUG!$H$3:$H$100),"-") -> 4999999591 | H16: =E16*0.07% -> 3492017.6 | I16: =SUMIF(AUG!B:B, B16, AUG!K:K) -> 11403045 | J16: =G16-E16-H16 -> 7911027 | O16: =IFERROR(SUM( INDEX($C:$C,MATCH($N16,$A:$A,0)+1): INDEX($C:$C,MATCH($N16&"_TOTAL",$A:$A,0)-1) ),0) -> 0 | P16: =IFERROR(AVERAGE( INDEX(D:D,MATCH($N16,$A:$A,0)+1): INDEX(D:D,MATCH($N16&"_TOTAL",$A:$A,0)-1) ),0) -> 0 | Q16: =IFERROR(SUM( INDEX(E:E,MATCH($N16,$A:$A,0)+1): INDEX(E:E,MATCH($N16&"_TOTAL",$A:$A,0)-1) ),0) -> 0 | R16: =IFERROR(AVERAGE( INDEX(F:F,MATCH($N16,$A:$A,0)+1): INDEX(F:F,MATCH($N16&"_TOTAL",$A:$A,0)-1) ),0) -> 0 | S16: =IFERROR(SUM( INDEX(G:G,MATCH($N16,$A:$A,0)+1): INDEX(G:G,MATCH($N16&"_TOTAL",$A:$A,0)-1) ),0) -> 0 | T16: =IFERROR(SUM( INDEX(H:H,MATCH($N16,$A:$A,0)+1): INDEX(H:H,MATCH($N16&"_TOTAL",$A:$A,0)-1) ),0) -> 0 | U16: =IFERROR(SUM( INDEX(J:J,MATCH($N16,$A:$A,0)+1): INDEX(J:J,MATCH($N16&"_TOTAL",$A:$A,0)-1) ),0) -> 0
A17: =IF(ISBLANK(B17),"",TEXT(B17,"dddd")) -> Thursday | B17: 46247 | C17: =SUMIF(AUG!$B$3:$B$100, B17, AUG!$D$3:$D$100) -> 224482.63 | D17: =IFERROR(__xludf.DUMMYFUNCTION("IFNA(INDEX(FILTER(AUG!$E$3:$E$100, AUG!$B$3:$B$100=B17), 1), ""-"")"),17799.999999999996) -> 17800 | E17: =SUMIF(AUG!$B$3:$B$100, B17, AUG!$F$3:$F$100) -> 3991544223 | F17: =IFERROR(__xludf.DUMMYFUNCTION("IFNA(INDEX(FILTER(AUG!$G$3:$G$100, AUG!$B$3:$B$100=B17), 1), ""-"")"),17820.0) -> 17820 | G17: =IFNA(SUMIF(AUG!$B$3:$B$100,B17,AUG!$H$3:$H$100),"-") -> 3999999804 | H17: =E17*0.07% -> 2794081 | I17: =SUMIF(AUG!B:B, B17, AUG!K:K) -> 8455581.7 | J17: =G17-E17-H17 -> 5661500.8
A18: =IF(ISBLANK(B18),"",TEXT(B18,"dddd")) -> Friday | B18: 46248 | C18: =SUMIF(AUG!$B$3:$B$100, B18, AUG!$D$3:$D$100) -> 168760.54 | D18: =IFERROR(__xludf.DUMMYFUNCTION("IFNA(INDEX(FILTER(AUG!$E$3:$E$100, AUG!$B$3:$B$100=B18), 1), ""-"")"),17740.336250307795) -> 17740.336 | E18: =SUMIF(AUG!$B$3:$B$100, B18, AUG!$F$3:$F$100) -> 2992263337 | F18: =IFERROR(__xludf.DUMMYFUNCTION("IFNA(INDEX(FILTER(AUG!$G$3:$G$100, AUG!$B$3:$B$100=B18), 1), ""-"")"),17780.0) -> 17780 | G18: =IFNA(SUMIF(AUG!$B$3:$B$100,B18,AUG!$H$3:$H$100),"-") -> 2999999813 | H18: =E18*0.07% -> 2094584.3 | I18: =SUMIF(AUG!B:B, B18, AUG!K:K) -> 7736476.1 | J18: =G18-E18-H18 -> 5641891.7
A19: =IF(ISBLANK(B19),"",TEXT(B19,"dddd")) -> Saturday | B19: 46249 | C19: =SUMIF(AUG!$B$3:$B$100, B19, AUG!$D$3:$D$100) -> 98651.13 | D19: =IFERROR(__xludf.DUMMYFUNCTION("IFNA(INDEX(FILTER(AUG!$E$3:$E$100, AUG!$B$3:$B$100=B19), 1), ""-"")"),17708.98471159263) -> 17708.985 | E19: =SUMIF(AUG!$B$3:$B$100, B19, AUG!$F$3:$F$100) -> 1746056544 | F19: =IFERROR(__xludf.DUMMYFUNCTION("IFNA(INDEX(FILTER(AUG!$G$3:$G$100, AUG!$B$3:$B$100=B19), 1), ""-"")"),17750.0) -> 17750 | G19: =IFNA(SUMIF(AUG!$B$3:$B$100,B19,AUG!$H$3:$H$100),"-") -> 1749999730 | H19: =E19*0.07% -> 1222239.6 | I19: =SUMIF(AUG!B:B, B19, AUG!K:K) -> 3943185.3 | J19: =G19-E19-H19 -> 2720945.7
A20: =IF(ISBLANK(B20),"",TEXT(B20,"dddd")) -> Sunday | B20: 46250 | C20: =SUMIF(AUG!$B$3:$B$100, B20, AUG!$D$3:$D$100) -> 0 | D20: =IFERROR(__xludf.DUMMYFUNCTION("IFNA(INDEX(FILTER(AUG!$E$3:$E$100, AUG!$B$3:$B$100=B20), 1), ""-"")"),"-") -> - | E20: =SUMIF(AUG!$B$3:$B$100, B20, AUG!$F$3:$F$100) -> 0 | F20: =IFERROR(__xludf.DUMMYFUNCTION("IFNA(INDEX(FILTER(AUG!$G$3:$G$100, AUG!$B$3:$B$100=B20), 1), ""-"")"),"-") -> - | G20: =IFNA(SUMIF(AUG!$B$3:$B$100,B20,AUG!$H$3:$H$100),"-") -> 0 | H20: =E20*0.07% -> 0 | I20: =SUMIF(AUG!B:B, B20, AUG!K:K) -> 0 | J20: =G20-E20-H20 -> 0
A21: =IF(ISBLANK(B21),"",TEXT(B21,"dddd")) -> Monday | B21: 46251 | C21: =SUMIF(AUG!$B$3:$B$100, B21, AUG!$D$3:$D$100) -> 56317.42 | D21: =IFERROR(__xludf.DUMMYFUNCTION("IFNA(INDEX(FILTER(AUG!$E$3:$E$100, AUG!$B$3:$B$100=B21), 1), ""-"")"),17732.924200571902) -> 17732.924 | E21: =SUMIF(AUG!$B$3:$B$100, B21, AUG!$F$3:$F$100) -> 9.9838322e+08 | F21: =IFERROR(__xludf.DUMMYFUNCTION("IFNA(INDEX(FILTER(AUG!$G$3:$G$100, AUG!$B$3:$B$100=B21), 1), ""-"")"),17745.0) -> 17745 | G21: =IFNA(SUMIF(AUG!$B$3:$B$100,B21,AUG!$H$3:$H$100),"-") -> 9.9999985e+08 | H21: =E21*0.07% -> 698868.25 | I21: =SUMIF(AUG!B:B, B21, AUG!K:K) -> 1616633.4 | J21: =G21-E21-H21 -> 917765.12
A22: =IF(ISBLANK(B22),"",TEXT(B22,"dddd")) -> Tuesday | B22: 46252 | C22: =SUMIF(AUG!$B$3:$B$100, B22, AUG!$D$3:$D$100) -> 28089.88 | D22: =IFERROR(__xludf.DUMMYFUNCTION("IFNA(INDEX(FILTER(AUG!$E$3:$E$100, AUG!$B$3:$B$100=B22), 1), ""-"")"),17770.0) -> 17770 | E22: =SUMIF(AUG!$B$3:$B$100, B22, AUG!$F$3:$F$100) -> 4.9915717e+08 | F22: =IFERROR(__xludf.DUMMYFUNCTION("IFNA(INDEX(FILTER(AUG!$G$3:$G$100, AUG!$B$3:$B$100=B22), 1), ""-"")"),17800.0) -> 17800 | G22: =IFNA(SUMIF(AUG!$B$3:$B$100,B22,AUG!$H$3:$H$100),"-") -> 499999864 | H22: =E22*0.07% -> 349410.02 | I22: =SUMIF(AUG!B:B, B22, AUG!K:K) -> 842696.4 | J22: =G22-E22-H22 -> 493286.38
A23: =IF(ISBLANK(B23),"",TEXT(B23,"dddd")) -> Wednesday | B23: 46253 | C23: =SUMIF(AUG!$B$3:$B$100, B23, AUG!$D$3:$D$100) -> 0 | D23: =IFERROR(__xludf.DUMMYFUNCTION("IFNA(INDEX(FILTER(AUG!$E$3:$E$100, AUG!$B$3:$B$100=B23), 1), ""-"")"),"-") -> - | E23: =SUMIF(AUG!$B$3:$B$100, B23, AUG!$F$3:$F$100) -> 0 | F23: =IFERROR(__xludf.DUMMYFUNCTION("IFNA(INDEX(FILTER(AUG!$G$3:$G$100, AUG!$B$3:$B$100=B23), 1), ""-"")"),"-") -> - | G23: =IFNA(SUMIF(AUG!$B$3:$B$100,B23,AUG!$H$3:$H$100),"-") -> 0 | H23: =E23*0.07% -> 0 | I23: =SUMIF(AUG!B:B, B23, AUG!K:K) -> 0 | J23: =G23-E23-H23 -> 0
A24: =IF(ISBLANK(B24),"",TEXT(B24,"dddd")) -> Thursday | B24: 46254 | C24: =SUMIF(AUG!$B$3:$B$100, B24, AUG!$D$3:$D$100) -> 0 | D24: =IFERROR(__xludf.DUMMYFUNCTION("IFNA(INDEX(FILTER(AUG!$E$3:$E$100, AUG!$B$3:$B$100=B24), 1), ""-"")"),"-") -> - | E24: =SUMIF(AUG!$B$3:$B$100, B24, AUG!$F$3:$F$100) -> 0 | F24: =IFERROR(__xludf.DUMMYFUNCTION("IFNA(INDEX(FILTER(AUG!$G$3:$G$100, AUG!$B$3:$B$100=B24), 1), ""-"")"),"-") -> - | G24: =IFNA(SUMIF(AUG!$B$3:$B$100,B24,AUG!$H$3:$H$100),"-") -> 0 | H24: =E24*0.07% -> 0 | I24: =SUMIF(AUG!B:B, B24, AUG!K:K) -> 0 | J24: =G24-E24-H24 -> 0
A25: =IF(ISBLANK(B25),"",TEXT(B25,"dddd")) -> Friday | B25: 46255 | C25: =SUMIF(AUG!$B$3:$B$100, B25, AUG!$D$3:$D$100) -> 0 | D25: =IFERROR(__xludf.DUMMYFUNCTION("IFNA(INDEX(FILTER(AUG!$E$3:$E$100, AUG!$B$3:$B$100=B25), 1), ""-"")"),"-") -> - | E25: =SUMIF(AUG!$B$3:$B$100, B25, AUG!$F$3:$F$100) -> 0 | F25: =IFERROR(__xludf.DUMMYFUNCTION("IFNA(INDEX(FILTER(AUG!$G$3:$G$100, AUG!$B$3:$B$100=B25), 1), ""-"")"),"-") -> - | G25: =IFNA(SUMIF(AUG!$B$3:$B$100,B25,AUG!$H$3:$H$100),"-") -> 0 | H25: =E25*0.07% -> 0 | I25: =SUMIF(AUG!B:B, B25, AUG!K:K) -> 0 | J25: =G25-E25-H25 -> 0
A26: =IF(ISBLANK(B26),"",TEXT(B26,"dddd")) -> Saturday | B26: 46256 | C26: =SUMIF(AUG!$B$3:$B$100, B26, AUG!$D$3:$D$100) -> 0 | D26: =IFERROR(__xludf.DUMMYFUNCTION("IFNA(INDEX(FILTER(AUG!$E$3:$E$100, AUG!$B$3:$B$100=B26), 1), ""-"")"),"-") -> - | E26: =SUMIF(AUG!$B$3:$B$100, B26, AUG!$F$3:$F$100) -> 0 | F26: =IFERROR(__xludf.DUMMYFUNCTION("IFNA(INDEX(FILTER(AUG!$G$3:$G$100, AUG!$B$3:$B$100=B26), 1), ""-"")"),"-") -> - | G26: =IFNA(SUMIF(AUG!$B$3:$B$100,B26,AUG!$H$3:$H$100),"-") -> 0 | H26: =E26*0.07% -> 0 | I26: =SUMIF(AUG!B:B, B26, AUG!K:K) -> 0 | J26: =G26-E26-H26 -> 0
A27: =IF(ISBLANK(B27),"",TEXT(B27,"dddd")) -> Sunday | B27: 46257 | C27: =SUMIF(AUG!$B$3:$B$100, B27, AUG!$D$3:$D$100) -> 0 | D27: =IFERROR(__xludf.DUMMYFUNCTION("IFNA(INDEX(FILTER(AUG!$E$3:$E$100, AUG!$B$3:$B$100=B27), 1), ""-"")"),"-") -> - | E27: =SUMIF(AUG!$B$3:$B$100, B27, AUG!$F$3:$F$100) -> 0 | F27: =IFERROR(__xludf.DUMMYFUNCTION("IFNA(INDEX(FILTER(AUG!$G$3:$G$100, AUG!$B$3:$B$100=B27), 1), ""-"")"),"-") -> - | G27: =IFNA(SUMIF(AUG!$B$3:$B$100,B27,AUG!$H$3:$H$100),"-") -> 0 | H27: =E27*0.07% -> 0 | I27: =SUMIF(AUG!B:B, B27, AUG!K:K) -> 0 | J27: =G27-E27-H27 -> 0
A28: =IF(ISBLANK(B28),"",TEXT(B28,"dddd")) -> Monday | B28: 46258 | C28: =SUMIF(AUG!$B$3:$B$100, B28, AUG!$D$3:$D$100) -> 0 | D28: =IFERROR(__xludf.DUMMYFUNCTION("IFNA(INDEX(FILTER(AUG!$E$3:$E$100, AUG!$B$3:$B$100=B28), 1), ""-"")"),"-") -> - | E28: =SUMIF(AUG!$B$3:$B$100, B28, AUG!$F$3:$F$100) -> 0 | F28: =IFERROR(__xludf.DUMMYFUNCTION("IFNA(INDEX(FILTER(AUG!$G$3:$G$100, AUG!$B$3:$B$100=B28), 1), ""-"")"),"-") -> - | G28: =IFNA(SUMIF(AUG!$B$3:$B$100,B28,AUG!$H$3:$H$100),"-") -> 0 | H28: =E28*0.07% -> 0 | I28: =SUMIF(AUG!B:B, B28, AUG!K:K) -> 0 | J28: =G28-E28-H28 -> 0
A29: =IF(ISBLANK(B29),"",TEXT(B29,"dddd")) -> Tuesday | B29: 46259 | C29: =SUMIF(AUG!$B$3:$B$100, B29, AUG!$D$3:$D$100) -> 0 | D29: =IFERROR(__xludf.DUMMYFUNCTION("IFNA(INDEX(FILTER(AUG!$E$3:$E$100, AUG!$B$3:$B$100=B29), 1), ""-"")"),"-") -> - | E29: =SUMIF(AUG!$B$3:$B$100, B29, AUG!$F$3:$F$100) -> 0 | F29: =IFERROR(__xludf.DUMMYFUNCTION("IFNA(INDEX(FILTER(AUG!$G$3:$G$100, AUG!$B$3:$B$100=B29), 1), ""-"")"),"-") -> - | G29: =IFNA(SUMIF(AUG!$B$3:$B$100,B29,AUG!$H$3:$H$100),"-") -> 0 | H29: =E29*0.07% -> 0 | I29: =SUMIF(AUG!B:B, B29, AUG!K:K) -> 0 | J29: =G29-E29-H29 -> 0
A30: =IF(ISBLANK(B30),"",TEXT(B30,"dddd")) -> Wednesday | B30: 46260 | C30: =SUMIF(AUG!$B$3:$B$100, B30, AUG!$D$3:$D$100) -> 0 | D30: =IFERROR(__xludf.DUMMYFUNCTION("IFNA(INDEX(FILTER(AUG!$E$3:$E$100, AUG!$B$3:$B$100=B30), 1), ""-"")"),"-") -> - | E30: =SUMIF(AUG!$B$3:$B$100, B30, AUG!$F$3:$F$100) -> 0 | F30: =IFERROR(__xludf.DUMMYFUNCTION("IFNA(INDEX(FILTER(AUG!$G$3:$G$100, AUG!$B$3:$B$100=B30), 1), ""-"")"),"-") -> - | G30: =IFNA(SUMIF(AUG!$B$3:$B$100,B30,AUG!$H$3:$H$100),"-") -> 0 | H30: =E30*0.07% -> 0 | I30: =SUMIF(AUG!B:B, B30, AUG!K:K) -> 0 | J30: =G30-E30-H30 -> 0
A31: =IF(ISBLANK(B31),"",TEXT(B31,"dddd")) -> Thursday | B31: 46261 | C31: =SUMIF(AUG!$B$3:$B$100, B31, AUG!$D$3:$D$100) -> 0 | D31: =IFERROR(__xludf.DUMMYFUNCTION("IFNA(INDEX(FILTER(AUG!$E$3:$E$100, AUG!$B$3:$B$100=B31), 1), ""-"")"),"-") -> - | E31: =SUMIF(AUG!$B$3:$B$100, B31, AUG!$F$3:$F$100) -> 0 | F31: =IFERROR(__xludf.DUMMYFUNCTION("IFNA(INDEX(FILTER(AUG!$G$3:$G$100, AUG!$B$3:$B$100=B31), 1), ""-"")"),"-") -> - | G31: =IFNA(SUMIF(AUG!$B$3:$B$100,B31,AUG!$H$3:$H$100),"-") -> 0 | H31: =E31*0.07% -> 0 | I31: =SUMIF(AUG!B:B, B31, AUG!K:K) -> 0 | J31: =G31-E31-H31 -> 0
A32: =IF(ISBLANK(B32),"",TEXT(B32,"dddd")) -> Friday | B32: 46262 | C32: =SUMIF(AUG!$B$3:$B$100, B32, AUG!$D$3:$D$100) -> 0 | D32: =IFERROR(__xludf.DUMMYFUNCTION("IFNA(INDEX(FILTER(AUG!$E$3:$E$100, AUG!$B$3:$B$100=B32), 1), ""-"")"),"-") -> - | E32: =SUMIF(AUG!$B$3:$B$100, B32, AUG!$F$3:$F$100) -> 0 | F32: =IFERROR(__xludf.DUMMYFUNCTION("IFNA(INDEX(FILTER(AUG!$G$3:$G$100, AUG!$B$3:$B$100=B32), 1), ""-"")"),"-") -> - | G32: =IFNA(SUMIF(AUG!$B$3:$B$100,B32,AUG!$H$3:$H$100),"-") -> 0 | H32: =E32*0.07% -> 0 | I32: =SUMIF(AUG!B:B, B32, AUG!K:K) -> 0 | J32: =G32-E32-H32 -> 0
A33: =IF(ISBLANK(B33),"",TEXT(B33,"dddd")) -> Saturday | B33: 46263 | C33: =SUMIF(AUG!$B$3:$B$100, B33, AUG!$D$3:$D$100) -> 0 | D33: =IFERROR(__xludf.DUMMYFUNCTION("IFNA(INDEX(FILTER(AUG!$E$3:$E$100, AUG!$B$3:$B$100=B33), 1), ""-"")"),"-") -> - | E33: =SUMIF(AUG!$B$3:$B$100, B33, AUG!$F$3:$F$100) -> 0 | F33: =IFERROR(__xludf.DUMMYFUNCTION("IFNA(INDEX(FILTER(AUG!$G$3:$G$100, AUG!$B$3:$B$100=B33), 1), ""-"")"),"-") -> - | G33: =IFNA(SUMIF(AUG!$B$3:$B$100,B33,AUG!$H$3:$H$100),"-") -> 0 | H33: =E33*0.07% -> 0 | I33: =SUMIF(AUG!B:B, B33, AUG!K:K) -> 0 | J33: =G33-E33-H33 -> 0
A34: =IF(ISBLANK(B34),"",TEXT(B34,"dddd")) -> Sunday | B34: 46264 | C34: =SUMIF(AUG!$B$3:$B$100, B34, AUG!$D$3:$D$100) -> 0 | D34: =IFERROR(__xludf.DUMMYFUNCTION("IFNA(INDEX(FILTER(AUG!$E$3:$E$100, AUG!$B$3:$B$100=B34), 1), ""-"")"),"-") -> - | E34: =SUMIF(AUG!$B$3:$B$100, B34, AUG!$F$3:$F$100) -> 0 | F34: =IFERROR(__xludf.DUMMYFUNCTION("IFNA(INDEX(FILTER(AUG!$G$3:$G$100, AUG!$B$3:$B$100=B34), 1), ""-"")"),"-") -> - | G34: =IFNA(SUMIF(AUG!$B$3:$B$100,B34,AUG!$H$3:$H$100),"-") -> 0 | H34: =E34*0.07% -> 0 | I34: =SUMIF(AUG!B:B, B34, AUG!K:K) -> 0 | J34: =G34-E34-H34 -> 0
A35: =IF(ISBLANK(B35),"",TEXT(B35,"dddd")) -> Monday | B35: 46265 | C35: =SUMIF(AUG!$B$3:$B$100, B35, AUG!$D$3:$D$100) -> 0 | D35: =IFERROR(__xludf.DUMMYFUNCTION("IFNA(INDEX(FILTER(AUG!$E$3:$E$100, AUG!$B$3:$B$100=B35), 1), ""-"")"),"-") -> - | E35: =SUMIF(AUG!$B$3:$B$100, B35, AUG!$F$3:$F$100) -> 0 | F35: =IFERROR(__xludf.DUMMYFUNCTION("IFNA(INDEX(FILTER(AUG!$G$3:$G$100, AUG!$B$3:$B$100=B35), 1), ""-"")"),"-") -> - | G35: =IFNA(SUMIF(AUG!$B$3:$B$100,B35,AUG!$H$3:$H$100),"-") -> 0 | H35: =E35*0.07% -> 0 | I35: =SUMIF(AUG!B:B, B35, AUG!K:K) -> 0 | J35: =G35-E35-H35 -> 0
A36: =CONCAT(A4,"_TOTAL") -> AUG_TOTAL | C36: =sum(C5:C35) -> 1139465.6 | D36: =IFERROR(IF(AVERAGE(D5:D35)=0,"-",AVERAGE(D5:D35)),"-") -> 17737.582 | E36: =sum(E5:E35) -> 20209889639 | F36: =IFERROR(IF(AVERAGE(F5:F35)=0,"-",AVERAGE(F5:F35)),"-") -> 17762.5 | G36: =sum(G5:G35) -> 20249998209 | H36: =sum(H5:H35) -> 14146923 | I36: =sum(I5:I35) -> 40108570 | J36: =sum(J5:J35) -> 25961647
A37: SEP
A38: =IF(ISBLANK(B38),"",TEXT(B38,"dddd")) -> Tuesday | B38: 46266 | C38: =SUMIF(SEP!$B$3:$B$101, B38, SEP!$D$3:$D$101) -> 263607.97 | D38: =IFERROR(__xludf.DUMMYFUNCTION("IFNA(INDEX(FILTER(SEP!$E$3:$E$100, SEP!$B$3:$B$100=B38), 1), ""-"")"),17631.61273918904) -> 17631.613 | E38: =SUMIF(SEP!$B$3:$B$101, B38, SEP!$F$3:$F$101) -> 4648033379 | F38: =IFERROR(__xludf.DUMMYFUNCTION("IFNA(INDEX(FILTER(SEP!$G$3:$G$100, SEP!$B$3:$B$100=B38), 1), ""-"")"),17675.0) -> 17675 | G38: =IFNA(SUMIF(SEP!$B$3:$B$900,B38,SEP!$H$3:$H$900),"-") -> 4656949679 | H38: =SUMIF(SEP!B:B, B38, SEP!J:J) -> 812399.11 | I38: =SUMIF(SEP!B:B, B38, SEP!K:K) -> 8916300.3 | J38: =G38-E38-H38 -> 8103901.2
A39: =IF(ISBLANK(B39),"",TEXT(B39,"dddd")) -> Wednesday | B39: 46267 | C39: =SUMIF(SEP!$B$3:$B$101, B39, SEP!$D$3:$D$101) -> 426052.27 | D39: =IFERROR(__xludf.DUMMYFUNCTION("IFNA(INDEX(FILTER(SEP!$E$3:$E$100, SEP!$B$3:$B$100=B39), 1), ""-"")"),17669.94174431459) -> 17669.942 | E39: =SUMIF(SEP!$B$3:$B$101, B39, SEP!$F$3:$F$101) -> 7522792266 | F39: =IFERROR(__xludf.DUMMYFUNCTION("IFNA(INDEX(FILTER(SEP!$G$3:$G$100, SEP!$B$3:$B$100=B39), 1), ""-"")"),17695.0) -> 17695 | G39: =IFNA(SUMIF(SEP!$B$3:$B$900,B39,SEP!$H$3:$H$900),"-") -> 7538920615 | H39: =SUMIF(SEP!B:B, B39, SEP!J:J) -> 3761396.1 | I39: =SUMIF(SEP!B:B, B39, SEP!K:K) -> 16128349 | J39: =G39-E39-H39 -> 12366953
A40: =IF(ISBLANK(B40),"",TEXT(B40,"dddd")) -> Thursday | B40: 46268 | C40: =SUMIF(SEP!$B$3:$B$101, B40, SEP!$D$3:$D$101) -> 605342.11 | D40: =IFERROR(__xludf.DUMMYFUNCTION("IFNA(INDEX(FILTER(SEP!$E$3:$E$100, SEP!$B$3:$B$100=B40), 1), ""-"")"),17628.226888880523) -> 17628.227 | E40: =SUMIF(SEP!$B$3:$B$101, B40, SEP!$F$3:$F$101) -> 10664145199 | F40: =IFERROR(__xludf.DUMMYFUNCTION("IFNA(INDEX(FILTER(SEP!$G$3:$G$100, SEP!$B$3:$B$100=B40), 1), ""-"")"),17665.0) -> 17665 | G40: =IFNA(SUMIF(SEP!$B$3:$B$900,B40,SEP!$H$3:$H$900),"-") -> 10685630581 | H40: =SUMIF(SEP!B:B, B40, SEP!J:J) -> 1495800.9 | I40: =SUMIF(SEP!B:B, B40, SEP!K:K) -> 21485382 | J40: =G40-E40-H40 -> 19989582
...

Sheet MONTHLY
A1: MONTHLY SUMMARY 2026
A2: MONTH | B2: NOMINAL | C2: RATE BUY (AVG) | D2: BUY | E2: RATE SELL (AVG) | F2: SELL | G2: FEE 0.07% | H2: PROFIT
A3: =IFERROR(__xludf.DUMMYFUNCTION("UNIQUE(FILTER(SUMMARY!A2:A153,(SUMMARY!A2:A153<>"""")*(COUNTIF(LEGEND!B2:B13,SUMMARY!A2:A153)>0)))"),"AUG") -> AUG | B3: {=IFERROR(SUM( INDEX(SUMMARY!$C:$C,MATCH($A3,SUMMARY!$A:$A,0)+1): INDEX(SUMMARY!$C:$C,MATCH($A3&"_TOTAL",SUMMARY!$A:$A,0)-1) ),0)} -> 1139465.6 | C3: {=IFERROR( AVERAGE( INDEX(SUMMARY!D:D,MATCH($A3,SUMMARY!$A:$A,0)+1): INDEX(SUMMARY!D:D,MATCH($A3&"_TOTAL",SUMMARY!$A:$A,0)-1) ),0)} -> 17737.582 | D3: {=IFERROR(SUM( INDEX(SUMMARY!E:E,MATCH($A3,SUMMARY!$A:$A,0)+1): INDEX(SUMMARY!E:E,MATCH($A3&"_TOTAL",SUMMARY!$A:$A,0)-1) ),0)} -> 20209889639 | E3: {=IFERROR(AVERAGE( INDEX(SUMMARY!F:F,MATCH($A3,SUMMARY!$A:$A,0)+1): INDEX(SUMMARY!F:F,MATCH($A3&"_TOTAL",SUMMARY!$A:$A,0)-1) ),0)} -> 17762.5 | F3: {=IFERROR(SUM( INDEX(SUMMARY!G:G,MATCH($A3,SUMMARY!$A:$A,0)+1): INDEX(SUMMARY!G:G,MATCH($A3&"_TOTAL",SUMMARY!$A:$A,0)-1) ),0)} -> 20249998209 | G3: {=IFERROR(SUM( INDEX(SUMMARY!H:H,MATCH($A3,SUMMARY!$A:$A,0)+1): INDEX(SUMMARY!H:H,MATCH($A3&"_TOTAL",SUMMARY!$A:$A,0)-1) ),0)} -> 14146923 | H3: {=IFERROR(SUM( INDEX(SUMMARY!J:J,MATCH($A3,SUMMARY!$A:$A,0)+1): INDEX(SUMMARY!J:J,MATCH($A3&"_TOTAL",SUMMARY!$A:$A,0)-1) ),0)} -> 25961647
A4: =IFERROR(__xludf.DUMMYFUNCTION("""COMPUTED_VALUE"""),"SEP") -> SEP | B4: {=IFERROR(SUM( INDEX(SUMMARY!$C:$C,MATCH($A4,SUMMARY!$A:$A,0)+1): INDEX(SUMMARY!$C:$C,MATCH($A4&"_TOTAL",SUMMARY!$A:$A,0)-1) ),0)} -> 11639891 | C4: {=IFERROR( AVERAGE( INDEX(SUMMARY!D:D,MATCH($A4,SUMMARY!$A:$A,0)+1): INDEX(SUMMARY!D:D,MATCH($A4&"_TOTAL",SUMMARY!$A:$A,0)-1) ),0)} -> 17635.512 | D4: {=IFERROR(SUM( INDEX(SUMMARY!E:E,MATCH($A4,SUMMARY!$A:$A,0)+1): INDEX(SUMMARY!E:E,MATCH($A4&"_TOTAL",SUMMARY!$A:$A,0)-1) ),0)} -> 205573414297 | E4: {=IFERROR(AVERAGE( INDEX(SUMMARY!F:F,MATCH($A4,SUMMARY!$A:$A,0)+1): INDEX(SUMMARY!F:F,MATCH($A4&"_TOTAL",SUMMARY!$A:$A,0)-1) ),0)} -> 17663.643 | F4: {=IFERROR(SUM( INDEX(SUMMARY!G:G,MATCH($A4,SUMMARY!$A:$A,0)+1): INDEX(SUMMARY!G:G,MATCH($A4&"_TOTAL",SUMMARY!$A:$A,0)-1) ),0)} -> 205910516613 | G4: =IFERROR(SUM( INDEX(#REF!,MATCH($K4,$A:$A,0)+1): INDEX(#REF!,MATCH($K4&"_TOTAL",$A:$A,0)-1) ),0) -> 0 | H4: {=IFERROR(SUM( INDEX(SUMMARY!J:J,MATCH($A4,SUMMARY!$A:$A,0)+1): INDEX(SUMMARY!J:J,MATCH($A4&"_TOTAL",SUMMARY!$A:$A,0)-1) ),0)} -> 2.9364768e+08
A5: =IFERROR(__xludf.DUMMYFUNCTION("""COMPUTED_VALUE"""),"OCT") -> OCT | B5: {=IFERROR(SUM( INDEX(SUMMARY!$C:$C,MATCH($A5,SUMMARY!$A:$A,0)+1): INDEX(SUMMARY!$C:$C,MATCH($A5&"_TOTAL",SUMMARY!$A:$A,0)-1) ),0)} -> 0 | C5: {=IFERROR( AVERAGE( INDEX(SUMMARY!D:D,MATCH($A5,SUMMARY!$A:$A,0)+1): INDEX(SUMMARY!D:D,MATCH($A5&"_TOTAL",SUMMARY!$A:$A,0)-1) ),0)} -> 0 | D5: {=IFERROR(SUM( INDEX(SUMMARY!E:E,MATCH($A5,SUMMARY!$A:$A,0)+1): INDEX(SUMMARY!E:E,MATCH($A5&"_TOTAL",SUMMARY!$A:$A,0)-1) ),0)} -> 0 | E5: {=IFERROR(AVERAGE( INDEX(SUMMARY!F:F,MATCH($A5,SUMMARY!$A:$A,0)+1): INDEX(SUMMARY!F:F,MATCH($A5&"_TOTAL",SUMMARY!$A:$A,0)-1) ),0)} -> 0 | F5: {=IFERROR(SUM( INDEX(SUMMARY!G:G,MATCH($A5,SUMMARY!$A:$A,0)+1): INDEX(SUMMARY!G:G,MATCH($A5&"_TOTAL",SUMMARY!$A:$A,0)-1) ),0)} -> 0 | G5: =IFERROR(SUM( INDEX(#REF!,MATCH($K5,$A:$A,0)+1): INDEX(#REF!,MATCH($K5&"_TOTAL",$A:$A,0)-1) ),0) -> 0 | H5: {=IFERROR(SUM( INDEX(SUMMARY!J:J,MATCH($A5,SUMMARY!$A:$A,0)+1): INDEX(SUMMARY!J:J,MATCH($A5&"_TOTAL",SUMMARY!$A:$A,0)-1) ),0)} -> 0
A6: =IFERROR(__xludf.DUMMYFUNCTION("""COMPUTED_VALUE"""),"NOV") -> NOV | B6: {=IFERROR(SUM( INDEX(SUMMARY!$C:$C,MATCH($A6,SUMMARY!$A:$A,0)+1): INDEX(SUMMARY!$C:$C,MATCH($A6&"_TOTAL",SUMMARY!$A:$A,0)-1) ),0)} -> 0 | C6: {=IFERROR( AVERAGE( INDEX(SUMMARY!D:D,MATCH($A6,SUMMARY!$A:$A,0)+1): INDEX(SUMMARY!D:D,MATCH($A6&"_TOTAL",SUMMARY!$A:$A,0)-1) ),0)} -> 0 | D6: {=IFERROR(SUM( INDEX(SUMMARY!E:E,MATCH($A6,SUMMARY!$A:$A,0)+1): INDEX(SUMMARY!E:E,MATCH($A6&"_TOTAL",SUMMARY!$A:$A,0)-1) ),0)} -> 0 | E6: {=IFERROR(AVERAGE( INDEX(SUMMARY!F:F,MATCH($A6,SUMMARY!$A:$A,0)+1): INDEX(SUMMARY!F:F,MATCH($A6&"_TOTAL",SUMMARY!$A:$A,0)-1) ),0)} -> 0 | F6: {=IFERROR(SUM( INDEX(SUMMARY!G:G,MATCH($A6,SUMMARY!$A:$A,0)+1): INDEX(SUMMARY!G:G,MATCH($A6&"_TOTAL",SUMMARY!$A:$A,0)-1) ),0)} -> 0 | G6: =IFERROR(SUM( INDEX(#REF!,MATCH($K6,$A:$A,0)+1): INDEX(#REF!,MATCH($K6&"_TOTAL",$A:$A,0)-1) ),0) -> 0 | H6: {=IFERROR(SUM( INDEX(SUMMARY!J:J,MATCH($A6,SUMMARY!$A:$A,0)+1): INDEX(SUMMARY!J:J,MATCH($A6&"_TOTAL",SUMMARY!$A:$A,0)-1) ),0)} -> 0
A7: =IFERROR(__xludf.DUMMYFUNCTION("""COMPUTED_VALUE"""),"DEC") -> DEC | B7: {=IFERROR(SUM( INDEX(SUMMARY!$C:$C,MATCH($A7,SUMMARY!$A:$A,0)+1): INDEX(SUMMARY!$C:$C,MATCH($A7&"_TOTAL",SUMMARY!$A:$A,0)-1) ),0)} -> 0 | C7: {=IFERROR( AVERAGE( INDEX(SUMMARY!D:D,MATCH($A7,SUMMARY!$A:$A,0)+1): INDEX(SUMMARY!D:D,MATCH($A7&"_TOTAL",SUMMARY!$A:$A,0)-1) ),0)} -> 0 | D7: {=IFERROR(SUM( INDEX(SUMMARY!E:E,MATCH($A7,SUMMARY!$A:$A,0)+1): INDEX(SUMMARY!E:E,MATCH($A7&"_TOTAL",SUMMARY!$A:$A,0)-1) ),0)} -> 0 | E7: {=IFERROR(AVERAGE( INDEX(SUMMARY!F:F,MATCH($A7,SUMMARY!$A:$A,0)+1): INDEX(SUMMARY!F:F,MATCH($A7&"_TOTAL",SUMMARY!$A:$A,0)-1) ),0)} -> 0 | F7: {=IFERROR(SUM( INDEX(SUMMARY!G:G,MATCH($A7,SUMMARY!$A:$A,0)+1): INDEX(SUMMARY!G:G,MATCH($A7&"_TOTAL",SUMMARY!$A:$A,0)-1) ),0)} -> 0 | G7: =IFERROR(SUM( INDEX(#REF!,MATCH($K7,$A:$A,0)+1): INDEX(#REF!,MATCH($K7&"_TOTAL",$A:$A,0)-1) ),0) -> 0 | H7: {=IFERROR(SUM( INDEX(SUMMARY!J:J,MATCH($A7,SUMMARY!$A:$A,0)+1): INDEX(SUMMARY!J:J,MATCH($A7&"_TOTAL",SUMMARY!$A:$A,0)-1) ),0)} -> 0
B8: {=IFERROR(SUM( INDEX(SUMMARY!$C:$C,MATCH($A8,SUMMARY!$A:$A,0)+1): INDEX(SUMMARY!$C:$C,MATCH($A8&"_TOTAL",SUMMARY!$A:$A,0)-1) ),0)} -> 0 | C8: {=IFERROR( AVERAGE( INDEX(SUMMARY!D:D,MATCH($A8,SUMMARY!$A:$A,0)+1): INDEX(SUMMARY!D:D,MATCH($A8&"_TOTAL",SUMMARY!$A:$A,0)-1) ),0)} -> 0 | D8: {=IFERROR(SUM( INDEX(SUMMARY!E:E,MATCH($A8,SUMMARY!$A:$A,0)+1): INDEX(SUMMARY!E:E,MATCH($A8&"_TOTAL",SUMMARY!$A:$A,0)-1) ),0)} -> 0 | E8: {=IFERROR(AVERAGE( INDEX(SUMMARY!F:F,MATCH($A8,SUMMARY!$A:$A,0)+1): INDEX(SUMMARY!F:F,MATCH($A8&"_TOTAL",SUMMARY!$A:$A,0)-1) ),0)} -> 0 | F8: {=IFERROR(SUM( INDEX(SUMMARY!G:G,MATCH($A8,SUMMARY!$A:$A,0)+1): INDEX(SUMMARY!G:G,MATCH($A8&"_TOTAL",SUMMARY!$A:$A,0)-1) ),0)} -> 0 | G8: =IFERROR(SUM( INDEX(#REF!,MATCH($K8,$A:$A,0)+1): INDEX(#REF!,MATCH($K8&"_TOTAL",$A:$A,0)-1) ),0) -> 0 | H8: {=IFERROR(SUM( INDEX(SUMMARY!J:J,MATCH($A8,SUMMARY!$A:$A,0)+1): INDEX(SUMMARY!J:J,MATCH($A8&"_TOTAL",SUMMARY!$A:$A,0)-1) ),0)} -> 0
B9: {=IFERROR(SUM( INDEX(SUMMARY!$C:$C,MATCH($A9,SUMMARY!$A:$A,0)+1): INDEX(SUMMARY!$C:$C,MATCH($A9&"_TOTAL",SUMMARY!$A:$A,0)-1) ),0)} -> 0 | C9: {=IFERROR( AVERAGE( INDEX(SUMMARY!D:D,MATCH($A9,SUMMARY!$A:$A,0)+1): INDEX(SUMMARY!D:D,MATCH($A9&"_TOTAL",SUMMARY!$A:$A,0)-1) ),0)} -> 0 | D9: {=IFERROR(SUM( INDEX(SUMMARY!E:E,MATCH($A9,SUMMARY!$A:$A,0)+1): INDEX(SUMMARY!E:E,MATCH($A9&"_TOTAL",SUMMARY!$A:$A,0)-1) ),0)} -> 0 | E9: {=IFERROR(AVERAGE( INDEX(SUMMARY!F:F,MATCH($A9,SUMMARY!$A:$A,0)+1): INDEX(SUMMARY!F:F,MATCH($A9&"_TOTAL",SUMMARY!$A:$A,0)-1) ),0)} -> 0 | F9: {=IFERROR(SUM( INDEX(SUMMARY!G:G,MATCH($A9,SUMMARY!$A:$A,0)+1): INDEX(SUMMARY!G:G,MATCH($A9&"_TOTAL",SUMMARY!$A:$A,0)-1) ),0)} -> 0 | G9: =IFERROR(SUM( INDEX(#REF!,MATCH($K9,$A:$A,0)+1): INDEX(#REF!,MATCH($K9&"_TOTAL",$A:$A,0)-1) ),0) -> 0 | H9: {=IFERROR(SUM( INDEX(SUMMARY!J:J,MATCH($A9,SUMMARY!$A:$A,0)+1): INDEX(SUMMARY!J:J,MATCH($A9&"_TOTAL",SUMMARY!$A:$A,0)-1) ),0)} -> 0
B10: {=IFERROR(SUM( INDEX(SUMMARY!$C:$C,MATCH($A10,SUMMARY!$A:$A,0)+1): INDEX(SUMMARY!$C:$C,MATCH($A10&"_TOTAL",SUMMARY!$A:$A,0)-1) ),0)} -> 0 | C10: {=IFERROR( AVERAGE( INDEX(SUMMARY!D:D,MATCH($A10,SUMMARY!$A:$A,0)+1): INDEX(SUMMARY!D:D,MATCH($A10&"_TOTAL",SUMMARY!$A:$A,0)-1) ),0)} -> 0 | D10: {=IFERROR(SUM( INDEX(SUMMARY!E:E,MATCH($A10,SUMMARY!$A:$A,0)+1): INDEX(SUMMARY!E:E,MATCH($A10&"_TOTAL",SUMMARY!$A:$A,0)-1) ),0)} -> 0 | E10: {=IFERROR(AVERAGE( INDEX(SUMMARY!F:F,MATCH($A10,SUMMARY!$A:$A,0)+1): INDEX(SUMMARY!F:F,MATCH($A10&"_TOTAL",SUMMARY!$A:$A,0)-1) ),0)} -> 0 | F10: {=IFERROR(SUM( INDEX(SUMMARY!G:G,MATCH($A10,SUMMARY!$A:$A,0)+1): INDEX(SUMMARY!G:G,MATCH($A10&"_TOTAL",SUMMARY!$A:$A,0)-1) ),0)} -> 0 | G10: =IFERROR(SUM( INDEX(#REF!,MATCH($K10,$A:$A,0)+1): INDEX(#REF!,MATCH($K10&"_TOTAL",$A:$A,0)-1) ),0) -> 0 | H10: {=IFERROR(SUM( INDEX(SUMMARY!J:J,MATCH($A10,SUMMARY!$A:$A,0)+1): INDEX(SUMMARY!J:J,MATCH($A10&"_TOTAL",SUMMARY!$A:$A,0)-1) ),0)} -> 0
B11: {=IFERROR(SUM( INDEX(SUMMARY!$C:$C,MATCH($A11,SUMMARY!$A:$A,0)+1): INDEX(SUMMARY!$C:$C,MATCH($A11&"_TOTAL",SUMMARY!$A:$A,0)-1) ),0)} -> 0 | C11: {=IFERROR( AVERAGE( INDEX(SUMMARY!D:D,MATCH($A11,SUMMARY!$A:$A,0)+1): INDEX(SUMMARY!D:D,MATCH($A11&"_TOTAL",SUMMARY!$A:$A,0)-1) ),0)} -> 0 | D11: {=IFERROR(SUM( INDEX(SUMMARY!E:E,MATCH($A11,SUMMARY!$A:$A,0)+1): INDEX(SUMMARY!E:E,MATCH($A11&"_TOTAL",SUMMARY!$A:$A,0)-1) ),0)} -> 0 | E11: {=IFERROR(AVERAGE( INDEX(SUMMARY!F:F,MATCH($A11,SUMMARY!$A:$A,0)+1): INDEX(SUMMARY!F:F,MATCH($A11&"_TOTAL",SUMMARY!$A:$A,0)-1) ),0)} -> 0 | F11: {=IFERROR(SUM( INDEX(SUMMARY!G:G,MATCH($A11,SUMMARY!$A:$A,0)+1): INDEX(SUMMARY!G:G,MATCH($A11&"_TOTAL",SUMMARY!$A:$A,0)-1) ),0)} -> 0 | G11: =IFERROR(SUM( INDEX(#REF!,MATCH($K11,$A:$A,0)+1): INDEX(#REF!,MATCH($K11&"_TOTAL",$A:$A,0)-1) ),0) -> 0 | H11: {=IFERROR(SUM( INDEX(SUMMARY!J:J,MATCH($A11,SUMMARY!$A:$A,0)+1): INDEX(SUMMARY!J:J,MATCH($A11&"_TOTAL",SUMMARY!$A:$A,0)-1) ),0)} -> 0
B12: {=IFERROR(SUM( INDEX(SUMMARY!$C:$C,MATCH($A12,SUMMARY!$A:$A,0)+1): INDEX(SUMMARY!$C:$C,MATCH($A12&"_TOTAL",SUMMARY!$A:$A,0)-1) ),0)} -> 0 | C12: {=IFERROR( AVERAGE( INDEX(SUMMARY!D:D,MATCH($A12,SUMMARY!$A:$A,0)+1): INDEX(SUMMARY!D:D,MATCH($A12&"_TOTAL",SUMMARY!$A:$A,0)-1) ),0)} -> 0 | D12: {=IFERROR(SUM( INDEX(SUMMARY!E:E,MATCH($A12,SUMMARY!$A:$A,0)+1): INDEX(SUMMARY!E:E,MATCH($A12&"_TOTAL",SUMMARY!$A:$A,0)-1) ),0)} -> 0 | E12: {=IFERROR(AVERAGE( INDEX(SUMMARY!F:F,MATCH($A12,SUMMARY!$A:$A,0)+1): INDEX(SUMMARY!F:F,MATCH($A12&"_TOTAL",SUMMARY!$A:$A,0)-1) ),0)} -> 0 | F12: {=IFERROR(SUM( INDEX(SUMMARY!G:G,MATCH($A12,SUMMARY!$A:$A,0)+1): INDEX(SUMMARY!G:G,MATCH($A12&"_TOTAL",SUMMARY!$A:$A,0)-1) ),0)} -> 0 | G12: =IFERROR(SUM( INDEX(#REF!,MATCH($K12,$A:$A,0)+1): INDEX(#REF!,MATCH($K12&"_TOTAL",$A:$A,0)-1) ),0) -> 0 | H12: {=IFERROR(SUM( INDEX(SUMMARY!J:J,MATCH($A12,SUMMARY!$A:$A,0)+1): INDEX(SUMMARY!J:J,MATCH($A12&"_TOTAL",SUMMARY!$A:$A,0)-1) ),0)} -> 0
B13: {=IFERROR(SUM( INDEX(SUMMARY!$C:$C,MATCH($A13,SUMMARY!$A:$A,0)+1): INDEX(SUMMARY!$C:$C,MATCH($A13&"_TOTAL",SUMMARY!$A:$A,0)-1) ),0)} -> 0 | C13: {=IFERROR( AVERAGE( INDEX(SUMMARY!D:D,MATCH($A13,SUMMARY!$A:$A,0)+1): INDEX(SUMMARY!D:D,MATCH($A13&"_TOTAL",SUMMARY!$A:$A,0)-1) ),0)} -> 0 | D13: {=IFERROR(SUM( INDEX(SUMMARY!E:E,MATCH($A13,SUMMARY!$A:$A,0)+1): INDEX(SUMMARY!E:E,MATCH($A13&"_TOTAL",SUMMARY!$A:$A,0)-1) ),0)} -> 0 | E13: {=IFERROR(AVERAGE( INDEX(SUMMARY!F:F,MATCH($A13,SUMMARY!$A:$A,0)+1): INDEX(SUMMARY!F:F,MATCH($A13&"_TOTAL",SUMMARY!$A:$A,0)-1) ),0)} -> 0 | F13: {=IFERROR(SUM( INDEX(SUMMARY!G:G,MATCH($A13,SUMMARY!$A:$A,0)+1): INDEX(SUMMARY!G:G,MATCH($A13&"_TOTAL",SUMMARY!$A:$A,0)-1) ),0)} -> 0 | G13: =IFERROR(SUM( INDEX(#REF!,MATCH($K13,$A:$A,0)+1): INDEX(#REF!,MATCH($K13&"_TOTAL",$A:$A,0)-1) ),0) -> 0 | H13: {=IFERROR(SUM( INDEX(SUMMARY!J:J,MATCH($A13,SUMMARY!$A:$A,0)+1): INDEX(SUMMARY!J:J,MATCH($A13&"_TOTAL",SUMMARY!$A:$A,0)-1) ),0)} -> 0
B14: {=IFERROR(SUM( INDEX(SUMMARY!$C:$C,MATCH($A14,SUMMARY!$A:$A,0)+1): INDEX(SUMMARY!$C:$C,MATCH($A14&"_TOTAL",SUMMARY!$A:$A,0)-1) ),0)} -> 0 | C14: {=IFERROR( AVERAGE( INDEX(SUMMARY!D:D,MATCH($A14,SUMMARY!$A:$A,0)+1): INDEX(SUMMARY!D:D,MATCH($A14&"_TOTAL",SUMMARY!$A:$A,0)-1) ),0)} -> 0 | D14: {=IFERROR(SUM( INDEX(SUMMARY!E:E,MATCH($A14,SUMMARY!$A:$A,0)+1): INDEX(SUMMARY!E:E,MATCH($A14&"_TOTAL",SUMMARY!$A:$A,0)-1) ),0)} -> 0 | E14: {=IFERROR(AVERAGE( INDEX(SUMMARY!F:F,MATCH($A14,SUMMARY!$A:$A,0)+1): INDEX(SUMMARY!F:F,MATCH($A14&"_TOTAL",SUMMARY!$A:$A,0)-1) ),0)} -> 0 | F14: {=IFERROR(SUM( INDEX(SUMMARY!G:G,MATCH($A14,SUMMARY!$A:$A,0)+1): INDEX(SUMMARY!G:G,MATCH($A14&"_TOTAL",SUMMARY!$A:$A,0)-1) ),0)} -> 0 | G14: =IFERROR(SUM( INDEX(#REF!,MATCH($K14,$A:$A,0)+1): INDEX(#REF!,MATCH($K14&"_TOTAL",$A:$A,0)-1) ),0) -> 0 | H14: {=IFERROR(SUM( INDEX(SUMMARY!J:J,MATCH($A14,SUMMARY!$A:$A,0)+1): INDEX(SUMMARY!J:J,MATCH($A14&"_TOTAL",SUMMARY!$A:$A,0)-1) ),0)} -> 0
B15: {=IFERROR(SUM( INDEX(SUMMARY!$C:$C,MATCH($A15,SUMMARY!$A:$A,0)+1): INDEX(SUMMARY!$C:$C,MATCH($A15&"_TOTAL",SUMMARY!$A:$A,0)-1) ),0)} -> 0 | C15: {=IFERROR( AVERAGE( INDEX(SUMMARY!D:D,MATCH($A15,SUMMARY!$A:$A,0)+1): INDEX(SUMMARY!D:D,MATCH($A15&"_TOTAL",SUMMARY!$A:$A,0)-1) ),0)} -> 0 | D15: {=IFERROR(SUM( INDEX(SUMMARY!E:E,MATCH($A15,SUMMARY!$A:$A,0)+1): INDEX(SUMMARY!E:E,MATCH($A15&"_TOTAL",SUMMARY!$A:$A,0)-1) ),0)} -> 0 | E15: {=IFERROR(AVERAGE( INDEX(SUMMARY!F:F,MATCH($A15,SUMMARY!$A:$A,0)+1): INDEX(SUMMARY!F:F,MATCH($A15&"_TOTAL",SUMMARY!$A:$A,0)-1) ),0)} -> 0 | F15: {=IFERROR(SUM( INDEX(SUMMARY!G:G,MATCH($A15,SUMMARY!$A:$A,0)+1): INDEX(SUMMARY!G:G,MATCH($A15&"_TOTAL",SUMMARY!$A:$A,0)-1) ),0)} -> 0 | G15: =IFERROR(SUM( INDEX(#REF!,MATCH($K15,$A:$A,0)+1): INDEX(#REF!,MATCH($K15&"_TOTAL",$A:$A,0)-1) ),0) -> 0 | H15: {=IFERROR(SUM( INDEX(SUMMARY!J:J,MATCH($A15,SUMMARY!$A:$A,0)+1): INDEX(SUMMARY!J:J,MATCH($A15&"_TOTAL",SUMMARY!$A:$A,0)-1) ),0)} -> 0

Sheet BUY_JAN

Sheet BUY_FEB

Sheet BUY_MAR

Sheet BUY_APR

Sheet BUY_MAY

Sheet BUY_JUN

Sheet BUY_JUL

Sheet BUY_AUG
A1: Day | B1: Date | C1: ID | D1: Nominal | E1: Price | F1: Total | G1: >> AVG >> | H1: Date | I1: ID | J1: Nominal | K1: Total | L1: RATE | M1: >> DAILY >> | N1: Date | O1: Nominal | P1: Total | Q1: Rate | R1: Fee % | S1: Fee ($) | T1: GrandTotal | U1: Sisa | V1: Sisa (Rp)
A2: =IF(ISBLANK(B2),"",TEXT(B2,"dddd")) -> Monday | B2: 46244 | C2: 1 | D2: 27480.75 | E2: 17663 | F2: =D2*E2 -> 4.8539249e+08 | H2: {=INDEX(UNIQUE(B2:C999), , 1)} -> 46244 | I2: {=INDEX(UNIQUE(B2:C999), , 2)} -> 1 | J2: =SUMIFS($D$2:$D999, $B$2:$B999, H2, $C$2:$C999, I2) -> 55860.87 | K2: =SUMIFS($F$2:$F999, $B$2:$B999, H2, $C$2:$C999, I2) -> 9.8672731e+08 | L2: =IFERROR(K2/J2, 0) -> 17664.016 | N2: {=UNIQUE(H2:H100)} -> 46244 | O2: =SUMIF($H$2:$H999, N2, $J$2:$J999) -> 169529.07 | P2: =SUMIF($H$2:$H999, N2, $K$2:$K999) -> 2994242932 | Q2: =IF(N2="", "", IFERROR(P2/O2, "-")) -> 17662.121 | R2: 0.07 | S2: =O2*$R2% -> 118.67035 | T2: =O2-S2 -> 169410.4 | U2: =IFERROR(ROUND(ABS(VALUE(T2)-VALUE(SUMMARY!C14)), 2), "-") -> 160.95 | V2: =IFERROR(ROUND(VALUE(U2)*VALUE(Q2), 2), "-") -> 2842718.4 | X2: NOTE : sisa = grandtotal - nominal (summary) total pembelian - total transaksi
A3: =IF(ISBLANK(B3),"",TEXT(B3,"dddd")) -> Monday | B3: 46244 | C3: 1 | D3: 27480.75 | E3: 17665 | F3: =D3*E3 -> 4.8544745e+08 | H3: 46244 | I3: 2 | J3: =SUMIFS($D$2:$D1000, $B$2:$B1000, H3, $C$2:$C1000, I3) -> 53373.26 | K3: =SUMIFS($F$2:$F1000, $B$2:$B1000, H3, $C$2:$C1000, I3) -> 9.4283864e+08 | L3: =IFERROR(K3/J3, 0) -> 17665 | N3: 46245 | O3: =SUMIF($H$2:$H1000, N3, $J$2:$J1000) -> 110534.77 | P3: =SUMIF($H$2:$H1000, N3, $K$2:$K1000) -> 1957578144 | Q3: =IF(N3="", "", IFERROR(P3/O3, "-")) -> 17710.067 | R3: 0.07 | S3: =O3*$R3% -> 77.374339 | T3: =O3-S3 -> 110457.4 | U3: =IFERROR(ROUND(ABS(VALUE(T3)-VALUE(SUMMARY!C15)), 2), "-") -> 2409.73 | V3: =IFERROR(ROUND(VALUE(U3)*VALUE(Q3), 2), "-") -> 42676479
A4: =IF(ISBLANK(B4),"",TEXT(B4,"dddd")) -> Monday | B4: 46244 | C4: 1 | D4: 899.37 | E4: 17665 | F4: =D4*E4 -> 15887371 | H4: 46244 | I4: 3 | J4: =SUMIFS($D$2:$D1001, $B$2:$B1001, H4, $C$2:$C1001, I4) -> 60294.94 | K4: =SUMIFS($F$2:$F1001, $B$2:$B1001, H4, $C$2:$C1001, I4) -> 1064676987 | L4: =IFERROR(K4/J4, 0) -> 17657.817 | N4: 46246 | O4: =SUMIF($H$2:$H1001, N4, $J$2:$J1001) -> 281056.05 | P4: =SUMIF($H$2:$H1001, N4, $K$2:$K1001) -> 4994470881 | Q4: =IF(N4="", "", IFERROR(P4/O4, "-")) -> 17770.373 | R4: 0.07 | S4: =O4*$R4% -> 196.73924 | T4: =O4-S4 -> 280859.31 | U4: =IFERROR(ROUND(ABS(VALUE(T4)-VALUE(SUMMARY!C16)), 2), "-") -> 133.82 | V4: =IFERROR(ROUND(VALUE(U4)*VALUE(Q4), 2), "-") -> 2378031.3
A5: =IF(ISBLANK(B5),"",TEXT(B5,"dddd")) -> Monday | B5: 46244 | C5: 2 | D5: 3173.58 | E5: 17665 | F5: =D5*E5 -> 56061291 | H5: 46245 | I5: 1 | J5: =SUMIFS($D$2:$D1002, $B$2:$B1002, H5, $C$2:$C1002, I5) -> 53792.55 | K5: =SUMIFS($F$2:$F1002, $B$2:$B1002, H5, $C$2:$C1002, I5) -> 9.5246288e+08 | L5: =IFERROR(K5/J5, 0) -> 17706.223 | N5: 46247 | O5: =SUMIF($H$2:$H1002, N5, $J$2:$J1002) -> 224750.43 | P5: =SUMIF($H$2:$H1002, N5, $K$2:$K1002) -> 3996285414 | Q5: =IF(N5="", "", IFERROR(P5/O5, "-")) -> 17780.991 | R5: 0.07 | S5: =O5*$R5% -> 157.3253 | T5: =O5-S5 -> 224593.1 | U5: =IFERROR(ROUND(ABS(VALUE(T5)-VALUE(SUMMARY!C17)), 2), "-") -> 110.47 | V5: =IFERROR(ROUND(VALUE(U5)*VALUE(Q5), 2), "-") -> 1964266.1
A6: =IF(ISBLANK(B6),"",TEXT(B6,"dddd")) -> Monday | B6: 46244 | C6: 2 | D6: 49300.31 | E6: 17665 | F6: =D6*E6 -> 8.7088998e+08 | H6: 46245 | I6: 2 | J6: =SUMIFS($D$2:$D1003, $B$2:$B1003, H6, $C$2:$C1003, I6) -> 56742.22 | K6: =SUMIFS($F$2:$F1003, $B$2:$B1003, H6, $C$2:$C1003, I6) -> 1005115261 | L6: =IFERROR(K6/J6, 0) -> 17713.711 | N6: 46248 | O6: =SUMIF($H$2:$H1003, N6, $J$2:$J1003) -> 168761.53 | P6: =SUMIF($H$2:$H1003, N6, $K$2:$K1003) -> 2992276608 | Q6: =IF(N6="", "", IFERROR(P6/O6, "-")) -> 17730.798 | R6: 0.07 | S6: =O6*$R6% -> 118.13307 | T6: =O6-S6 -> 168643.4 | V6: =IFERROR(ROUND(VALUE(U6)*VALUE(Q6), 2), "-") -> 0
A7: =IF(ISBLANK(B7),"",TEXT(B7,"dddd")) -> Monday | B7: 46244 | C7: 2 | D7: 899.37 | E7: 17665 | F7: =D7*E7 -> 15887371 | H7: 46246 | I7: 1 | J7: =SUMIFS($D$2:$D1004, $B$2:$B1004, H7, $C$2:$C1004, I7) -> 56144.37 | K7: =SUMIFS($F$2:$F1004, $B$2:$B1004, H7, $C$2:$C1004, I7) -> 9.9814425e+08 | L7: =IFERROR(K7/J7, 0) -> 17778.172 | N7: 46249 | O7: =SUMIF($H$2:$H1004, N7, $J$2:$J1004) -> 92083.22 | P7: =SUMIF($H$2:$H1004, N7, $K$2:$K1004) -> 1629862445 | Q7: =IF(N7="", "", IFERROR(P7/O7, "-")) -> 17699.885 | R7: 0.07 | S7: =O7*$R7% -> 64.458254 | T7: =O7-S7 -> 92018.762 | V7: =IFERROR(ROUND(VALUE(U7)*VALUE(Q7), 2), "-") -> 0
A8: =IF(ISBLANK(B8),"",TEXT(B8,"dddd")) -> Monday | B8: 46244 | C8: 3 | D8: 1269.19 | E8: 17665 | F8: =D8*E8 -> 22420241 | H8: 46246 | I8: 2 | J8: =SUMIFS($D$2:$D1005, $B$2:$B1005, H8, $C$2:$C1005, I8) -> 56210.64 | K8: =SUMIFS($F$2:$F1005, $B$2:$B1005, H8, $C$2:$C1005, I8) -> 9.9924999e+08 | L8: =IFERROR(K8/J8, 0) -> 17776.883 | N8: 46251 | O8: =SUMIF($H$2:$H1005, N8, $J$2:$J1005) -> 56108.35 | P8: =SUMIF($H$2:$H1005, N8, $K$2:$K1005) -> 9.9468423e+08 | Q8: =IF(N8="", "", IFERROR(P8/O8, "-")) -> 17727.918 | R8: 0 | S8: =O8*$R8% -> 0 | T8: =O8-S8 -> 56108.35 | V8: =IFERROR(ROUND(VALUE(U8)*VALUE(Q8), 2), "-") -> 0
A9: =IF(ISBLANK(B9),"",TEXT(B9,"dddd")) -> Monday | B9: 46244 | C9: 3 | D9: 899.37 | E9: 17665 | F9: =D9*E9 -> 15887371 | H9: 46246 | I9: 3 | J9: =SUMIFS($D$2:$D1006, $B$2:$B1006, H9, $C$2:$C1006, I9) -> 56280.58 | K9: =SUMIFS($F$2:$F1006, $B$2:$B1006, H9, $C$2:$C1006, I9) -> 9.9943054e+08 | L9: =IFERROR(K9/J9, 0) -> 17758 | N9: 46252 | O9: =SUMIF($H$2:$H1006, N9, $J$2:$J1006) -> 27980.4 | P9: =SUMIF($H$2:$H1006, N9, $K$2:$K1006) -> 497211708 | Q9: =IF(N9="", "", IFERROR(P9/O9, "-")) -> 17770 | R9: 0 | S9: =O9*$R9% -> 0 | T9: =O9-S9 -> 27980.4 | V9: =IFERROR(ROUND(VALUE(U9)*VALUE(Q9), 2), "-") -> 0
A10: =IF(ISBLANK(B10),"",TEXT(B10,"dddd")) -> Monday | B10: 46244 | C10: 3 | D10: 1166.22 | E10: 17665 | F10: =D10*E10 -> 20601276 | H10: 46246 | I10: 4 | J10: =SUMIFS($D$2:$D1007, $B$2:$B1007, H10, $C$2:$C1007, I10) -> 56109.89 | K10: =SUMIFS($F$2:$F1007, $B$2:$B1007, H10, $C$2:$C1007, I10) -> 9.9692888e+08 | L10: =IFERROR(K10/J10, 0) -> 17767.436 | O10: =SUMIF($H$2:$H1007, N10, $J$2:$J1007) -> 0 | P10: =SUMIF($H$2:$H1007, N10, $K$2:$K1007) -> 0 | Q10: =IF(N10="", "", IFERROR(P10/O10, "-")) | R10: 0 | S10: =O10*$R10% -> 0 | T10: =O10-S10 -> 0 | V10: =IFERROR(ROUND(VALUE(U10)*VALUE(Q10), 2), "-") -> 0
A11: =IF(ISBLANK(B11),"",TEXT(B11,"dddd")) -> Monday | B11: 46244 | C11: 3 | D11: 19751.63 | E11: 17652 | F11: =D11*E11 -> 3.4865577e+08 | H11: 46246 | I11: 5 | J11: =SUMIFS($D$2:$D1008, $B$2:$B1008, H11, $C$2:$C1008, I11) -> 56310.57 | K11: =SUMIFS($F$2:$F1008, $B$2:$B1008, H11, $C$2:$C1008, I11) -> 1000717223 | L11: =IFERROR(K11/J11, 0) -> 17771.392 | O11: =SUMIF($H$2:$H1008, N11, $J$2:$J1008) -> 0 | P11: =SUMIF($H$2:$H1008, N11, $K$2:$K1008) -> 0 | Q11: =IF(N11="", "", IFERROR(P11/O11, "-")) | R11: 0 | S11: =O11*$R11% -> 0 | T11: =O11-S11 -> 0 | V11: =IFERROR(ROUND(VALUE(U11)*VALUE(Q11), 2), "-") -> 0
A12: =IF(ISBLANK(B12),"",TEXT(B12,"dddd")) -> Monday | B12: 46244 | C12: 3 | D12: 1998.61 | E12: 17652 | F12: =D12*E12 -> 35279464 | H12: 46247 | I12: 1 | J12: =SUMIFS($D$2:$D1009, $B$2:$B1009, H12, $C$2:$C1009, I12) -> 56064.56 | K12: =SUMIFS($F$2:$F1009, $B$2:$B1009, H12, $C$2:$C1009, I12) -> 997949168 | L12: =IFERROR(K12/J12, 0) -> 17800 | O12: =SUMIF($H$2:$H1009, N12, $J$2:$J1009) -> 0 | P12: =SUMIF($H$2:$H1009, N12, $K$2:$K1009) -> 0 | Q12: =IF(N12="", "", IFERROR(P12/O12, "-")) | R12: 0 | S12: =O12*$R12% -> 0 | T12: =O12-S12 -> 0 | V12: =IFERROR(ROUND(VALUE(U12)*VALUE(Q12), 2), "-") -> 0
